Workbook

Sheet Sheet1
A1: Categoria | B1: SubCategoria | C1: Sku | D1: PRODUCT NUMBER | F1: Size | G1: Precio | H1: Nombre | I1: Disponible | J1: Imagen | K1: Unidades | L1: Estado
A2: OLIVE OIL - OILS & LARD | B2: GOYA EXTRA VIRGIN OLIVE OIL | C2: 1103 | D2: 1103 | E2: =IF(C2=D2, "Same","New") -> Same | F2: 3 OZ | G2: 77.5 | H2: EXTRA VIRGIN OLIVE OIL 3 OZ | I2: =[1]Sheet1!I2 -> 1045 | J2: =C2 & "_A1C1.webp" -> 1103_A1C1.webp | K2: =Sheet4!E2 -> 36
A3: OLIVE OIL - OILS & LARD | B3: GOYA EXTRA VIRGIN OLIVE OIL | C3: 1105 | D3: 1105 | E3: =IF(C3=D3, "Same","New") -> Same | F3: 8.5 OZ | G3: 131.95 | H3: EXTRA VIRGIN OLIVE OIL 8.5 OZ | I3: =[1]Sheet1!I3 -> 3063 | J3: =C3 & "_A1C1.webp" -> 1105_A1C1.webp | K3: =Sheet4!E3 -> 25
A4: OLIVE OIL - OILS & LARD | B4: GOYA EXTRA VIRGIN OLIVE OIL | C4: 1107 | D4: 1107 | E4: =IF(C4=D4, "Same","New") -> Same | F4: 17 OZ | G4: 120.5 | H4: EXTRA VIRGIN OLIVE OIL 17 OZ | I4: =[1]Sheet1!I4 -> 3740 | J4: =C4 & "_A1C1.webp" -> 1107_A1C1.webp | K4: =Sheet4!E4 -> 12
A5: OLIVE OIL - OILS & LARD | B5: GOYA EXTRA VIRGIN OLIVE OIL | C5: 1108 | D5: 1108 | E5: =IF(C5=D5, "Same","New") -> Same | F5: 25.4 OZ | G5: 134.95 | H5: EXTRA VIRGIN OLIVE OIL 25.4 OZ | I5: =[1]Sheet1!I5 -> 243 | J5: =C5 & "_A1C1.webp" -> 1108_A1C1.webp | K5: =Sheet4!E5 -> 9
A6: OLIVE OIL - OILS & LARD | B6: GOYA EXTRA VIRGIN OLIVE OIL | C6: 1109 | D6: 1109 | E6: =IF(C6=D6, "Same","New") -> Same | F6: 34 OZ | G6: 169.95 | H6: EXTRA VIRGIN OLIVE OIL 34 OZ | I6: =[1]Sheet1!I6 -> 1434 | J6: =C6 & "_A1C1.webp" -> 1109_A1C1.webp | K6: =Sheet4!E6 -> 9
A7: OLIVE OIL - OILS & LARD | B7: GOYA EXTRA VIRGIN OLIVE OIL | C7: 1111 | D7: 1111 | E7: =IF(C7=D7, "Same","New") -> Same | F7: 50.7 OZ | G7: 168.95 | H7: EXTRA VIRGIN OLIVE OIL 50.7 OZ | I7: =[1]Sheet1!I7 -> 134 | J7: =C7 & "_A1C1.webp" -> 1111_A1C1.webp | K7: =Sheet4!E7 -> 6
A8: OLIVE OIL - OILS & LARD | B8: GOYA EXTRA VIRGIN OLIVE OIL | C8: 1120 | D8: 1120 | E8: =IF(C8=D8, "Same","New") -> Same | F8: 24 OZ | G8: 171.95 | H8: EXTRA VIRGIN OLIVE OIL 24 OZ | I8: =[1]Sheet1!I8 -> 3 | J8: =C8 & "_A1C1.webp" -> 1120_A1C1.webp | K8: =Sheet4!E8 -> 12
A9: OLIVE OIL - OILS & LARD | B9: GOYA EXTRA VIRGIN OLIVE OIL | C9: 1128 | D9: 1128 | E9: =IF(C9=D9, "Same","New") -> Same | F9: 102 OZ | G9: 170.5 | H9: EXTRA VIRGIN OLIVE OIL 3 LTS | I9: =[1]Sheet1!I9 -> 78 | J9: =C9 & "_A1C1.webp" -> 1128_A1C1.webp | K9: =Sheet4!E9 -> 3
A10: OLIVE OIL - OILS & LARD | B10: GOYA EXTRA VIRGIN OLIVE OIL | C10: 1130 | D10: 1130 | E10: =IF(C10=D10, "Same","New") -> Same | F10: 17 OZ | G10: 144.95 | H10: GOYA UNICO XTRA VIRGIN OLV OIL | I10: =[1]Sheet1!I10 -> 67 | J10: =C10 & "_A1C1.webp" -> 1130_A1C1.webp | K10: =Sheet4!E10 -> 12
A11: OLIVE OIL - OILS & LARD | B11: GOYA EXTRA VIRGIN OLIVE OIL | C11: 1133 | D11: 1133 | E11: =IF(C11=D11, "Same","New") -> Same | F11: 17 OZ | G11: 135.35 | H11: ORGANIC EXTRA VIRGIN OLIVE OIL | I11: =[1]Sheet1!I11 -> 124 | J11: =C11 & "_A1C1.webp" -> 1133_A1C1.webp | K11: =Sheet4!E11 -> 12
A12: OLIVE OIL - OILS & LARD | B12: GOYA OLIVE OIL | C12: 1141 | D12: 1141 | E12: =IF(C12=D12, "Same","New") -> Same | F12: 8.5 OZ | G12: 113.5 | H12: PURO OLIVE OIL 8.5 OZ | I12: =[1]Sheet1!I12 -> 495 | J12: =C12 & "_A1C1.webp" -> 1141_A1C1.webp | K12: =Sheet4!E12 -> 25
A13: OLIVE OIL - OILS & LARD | B13: GOYA OLIVE OIL | C13: 1142 | D13: 1142 | E13: =IF(C13=D13, "Same","New") -> Same | F13: 17 OZ | G13: 103.95 | H13: PURO OLIVE OIL 17 OZ | I13: =[1]Sheet1!I13 -> 436 | J13: =C13 & "_A1C1.webp" -> 1142_A1C1.webp | K13: =Sheet4!E13 -> 12
... A19: OLIVE OIL - OILS & LARD | B19: OLE-O OLIVE OIL BLEND | C19: 1186 | D19: 1186 | E19: =IF(C19=D19, "Same","New") -> Same | F19: 50.7 OZ | G19: 91.5 | H19: OLE-O OLIVE OIL BLEND | I19: =[1]Sheet1!I19 -> 327 | J19: =C19 & "_A1C1.webp" -> 1186_A1C1.webp | K19: =Sheet4!E19 -> 6
A20: OLIVE OIL - OILS & LARD | B20: GOYA EXTRA VIRGIN OLIVE OIL WITH TRUFFLE FLAVOR | C20: 1188 | D20: 1188 | E20: =IF(C20=D20, "Same","New") -> Same | F20: 8.5 OZ | G20: 76.95 | H20: EV OLIVE OIL TRUFFLE FLV | I20: =[1]Sheet1!I20 -> 83 | J20: =C20 & "_A1C1.webp" -> 1188_A1C1.webp | K20: =Sheet4!E20 -> 12 | L20: New
A21: MARINADES - VINEGAR & WINE | B21: GOYA VINEGAR | C21: 1190 | D21: 1190 | E21: =IF(C21=D21, "Same","New") -> Same | F21: 8.5 OZ | G21: 26.5 | H21: VINEGAR BALSAMIC 8.50 OZ. | I21: =[1]Sheet1!I21 -> 168 | J21: =C21 & "_A1C1.webp" -> 1190_A1C1.webp | K21: =Sheet4!E21 -> 9
A22: MARINADES - VINEGAR & WINE | B22: GOYA VINEGAR | C22: 1191 | D22: 1191 | E22: =IF(C22=D22, "Same","New") -> Same | F22: 8.5 OZ | G22: 24.5 | H22: SHERRY VINEGAR 8.50 OZ. | I22: =[1]Sheet1!I22 -> 28 | J22: =C22 & "_A1C1.webp" -> 1191_A1C1.webp | K22: =Sheet4!E22 -> 9
A23: MARINADES - VINEGAR & WINE | B23: GOYA VINEGAR | C23: 1192 | D23: 1192 | E23: =IF(C23=D23, "Same","New") -> Same | F23: 8.5 OZ | G23: 29.95 | H23: SHERRY VINEGAR RESERVA 8.50 OZ | I23: =[1]Sheet1!I23 -> 32 | J23: =C23 & "_A1C1.webp" -> 1192_A1C1.webp | K23: =Sheet4!E23 -> 9
A24: OLIVE OIL - OILS & LARD | B24: GOYA EXTRA VIRGIN OLIVE OIL WITH GARLIC FLAVOR | C24: 1195 | D24: 1195 | E24: =IF(C24=D24, "Same","New") -> Same | F24: 8.5 OZ | G24: 76.95 | H24: GARLIC EXTRA VIRGIN OLIVE OIL | I24: =[1]Sheet1!I24 -> 251 | J24: =C24 & "_A1C1.webp" -> 1195_A1C1.webp | K24: =Sheet4!E24 -> 12
A25: OLIVE OIL - OILS & LARD | B25: GOYA EXTRA VIRGIN OLIVE OIL SPRAY | C25: 1199 | D25: 1199 | E25: =IF(C25=D25, "Same","New") -> Same | F25: 5 OZ | G25: 43.5 | H25: EXTRA VIRGIN OLIVE OIL SPRAY | I25: =[1]Sheet1!I25 -> 550 | J25: =C25 & "_A1C1.webp" -> 1199_A1C1.webp | K25: =Sheet4!E25 -> 12 | L25: New
A26: OLIVE OIL - OILS & LARD | B26: GOYA COOKING OILS & LARD | C26: 1222 | D26: 1222 | E26: =IF(C26=D26, "Same","New") -> Same | F26: 280 OZ | G26: 61.5 | H26: PURE CORN OIL 280 OZ | I26: =[1]Sheet1!I26 -> 155 | J26: =C26 & "_A1C1.webp" -> 1222_A1C1.webp | K26: =Sheet4!E26 -> 2
A27: OLIVE OIL - OILS & LARD | B27: GOYA COOKING OILS & LARD | C27: 1227 | D27: 1227 | E27: =IF(C27=D27, "Same","New") -> Same | F27: 16 OZ | G27: 47.5 | H27: PURE CORN OIL 16 OZ | I27: =[1]Sheet1!I27 -> 526 | J27: =C27 & "_A1C1.webp" -> 1227_A1C1.webp | K27: =Sheet4!E27 -> 24
A28: OLIVE OIL - OILS & LARD | B28: GOYA COOKING OILS & LARD | C28: 1229 | D28: 1229 | E28: =IF(C28=D28, "Same","New") -> Same | F28: 24 OZ | G28: 34.5 | H28: PURE CORN OIL 24 OZ | I28: =[1]Sheet1!I28 -> 917 | J28: =C28 & "_A1C1.webp" -> 1229_A1C1.webp | K28: =Sheet4!E28 -> 12
A29: OLIVE OIL - OILS & LARD | B29: GOYA COOKING OILS & LARD | C29: 1231 | D29: 1231 | E29: =IF(C29=D29, "Same","New") -> Same | F29: 48 OZ | G29: 45.5 | H29: PURE CORN OIL 48 OZ | I29: =[1]Sheet1!I29 -> 703 | J29: =C29 & "_A1C1.webp" -> 1231_A1C1.webp | K29: =Sheet4!E29 -> 9
A30: OLIVE OIL - OILS & LARD | B30: GOYA COOKING OILS & LARD | C30: 1233 | D30: 1233 | E30: =IF(C30=D30, "Same","New") -> Same | F30: 128 OZ | G30: 74.5 | H30: PURE CORN OIL 1 GAL | I30: =[1]Sheet1!I30 -> 164 | J30: =C30 & "_A1C1.webp" -> 1233_A1C1.webp | K30: =Sheet4!E30 -> 6
A31: OLIVE OIL - OILS & LARD | B31: GOYA COOKING OILS & LARD | C31: 1234 | D31: 1234 | E31: =IF(C31=D31, "Same","New") -> Same | F31: 96 OZ | G31: 59.95 | H31: PURE CORN OIL 96 OZ | I31: =[1]Sheet1!I31 -> 412 | J31: =C31 & "_A1C1.webp" -> 1234_A1C1.webp | K31: =Sheet4!E31 -> 6
A32: OLIVE OIL - OILS & LARD | B32: GOYA COOKING OILS & LARD | C32: 1235 | D32: 1235 | E32: =IF(C32=D32, "Same","New") -> Same | F32: 16 OZ | G32: 42.95 | H32: VEGETABLE OIL 16 OZ | I32: =[1]Sheet1!I32 -> 610 | J32: =C32 & "_A1C1.webp" -> 1235_A1C1.webp | K32: =Sheet4!E32 -> 24
A33: OLIVE OIL - OILS & LARD | B33: GOYA COOKING OILS & LARD | C33: 1237 | D33: 1237 | E33: =IF(C33=D33, "Same","New") -> Same | F33: 24 OZ | G33: 30.5 | H33: VEGETABLE OIL 24 OZ | I33: =[1]Sheet1!I33 -> 1080 | J33: =C33 & "_A1C1.webp" -> 1237_A1C1.webp | K33: =Sheet4!E33 -> 12
A34: OLIVE OIL - OILS & LARD | B34: GOYA COOKING OILS & LARD | C34: 1239 | D34: 1239 | E34: =IF(C34=D34, "Same","New") -> Same | F34: 48 OZ | G34: 40.5 | H34: VEGETABLE OIL 48 OZ | I34: =[1]Sheet1!I34 -> 972 | J34: =C34 & "_A1C1.webp" -> 1239_A1C1.webp | K34: =Sheet4!E34 -> 9
A35: OLIVE OIL - OILS & LARD | B35: GOYA COOKING OILS & LARD | C35: 1240 | D35: 1240 | E35: =IF(C35=D35, "Same","New") -> Same | F35: 96 OZ | G35: 53.95 | H35: VEGETABLE OIL 96 OZ | I35: =[1]Sheet1!I35 -> 163 | J35: =C35 & "_A1C1.webp" -> 1240_A1C1.webp | K35: =Sheet4!E35 -> 6
A36: OLIVE OIL - OILS & LARD | B36: GOYA COOKING OILS & LARD | C36: 1241 | D36: 1241 | E36: =IF(C36=D36, "Same","New") -> Same | F36: 128 OZ | G36: 66.5 | H36: VEGETABLE OIL 1 GAL | I36: =[1]Sheet1!I36 -> 411 | J36: =C36 & "_A1C1.webp" -> 1241_A1C1.webp | K36: =Sheet4!E36 -> 6
A37: OLIVE OIL - OILS & LARD | B37: GOYA COOKING OILS & LARD | C37: 1250 | D37: 1250 | E37: =IF(C37=D37, "Same","New") -> Same | F37: 48 OZ | G37: 39.95 | H37: CANOLA OIL 48 OZ | I37: =[1]Sheet1!I37 -> 233 | J37: =C37 & "_A1C1.webp" -> 1250_A1C1.webp | K37: =Sheet4!E37 -> 9
A38: OLIVE OIL - OILS & LARD | B38: GOYA COOKING OILS & LARD | C38: 1251 | D38: 1251 | E38: =IF(C38=D38, "Same","New") -> Same | F38: 96 OZ | G38: 53.5 | H38: CANOLA OIL 96 OZ | I38: =[1]Sheet1!I38 -> 166 | J38: =C38 & "_A1C1.webp" -> 1251_A1C1.webp | K38: =Sheet4!E38 -> 6
A39: OLIVE OIL - OILS & LARD | B39: GOYA AVOCADO OIL | C39: 1255 | D39: 1255 | E39: =IF(C39=D39, "Same","New") -> Same | F39: 25.4 OZ | G39: 55.95 | H39: GOYA AVOCADO OIL 25.4 OZ | I39: =[1]Sheet1!I39 -> 1608 | J39: =C39 & "_A1C1.webp" -> 1255_A1C1.webp | K39: =Sheet4!E39 -> 6 | L39: New
A40: OLIVES & PICKLED PRODUCTS/ OLIVES | B40: PERDIGON/ MANZANILLA COCKTAIL OLIVES | C40: 1304 | D40: 1304 | E40: =IF(C40=D40, "Same","New") -> Same | F40: 9.5 OZ | G40: 18.95 | H40: PERDIGON OLIVES 12/9.5 OZ | I40: =[1]Sheet1!I40 -> 63 | J40: =C40 & "_A1C1.webp" -> 1304_A1C1.webp | K40: =Sheet4!E40 -> 12
A41: OLIVES & PICKLED PRODUCTS/ OLIVES | B41: GOYA JAR/ MANZANILLA OLIVES | C41: 1307 | D41: 1307 | E41: =IF(C41=D41, "Same","New") -> Same | F41: 3.75 OZ | G41: 16.95 | H41: MANZANILLA OLIVES | I41: =[1]Sheet1!I41 -> 374 | J41: =C41 & "_A1C1.webp" -> 1307_A1C1.webp | K41: =Sheet4!E41 -> 12
A42: OLIVES & PICKLED PRODUCTS/ OLIVES | B42: GOYA JAR/ MANZANILLA OLIVES | C42: 1309 | D42: 1309 | E42: =IF(C42=D42, "Same","New") -> Same | F42: 9.5 OZ | G42: 27.25 | H42: MANZANILLA OLIVES 9.5 OZ | I42: =[1]Sheet1!I42 -> 662 | J42: =C42 & "_A1C1.webp" -> 1309_A1C1.webp | K42: =Sheet4!E42 -> 12
A43: OLIVES & PICKLED PRODUCTS/ OLIVES | B43: PERDIGON/ MANZANILLA COCKTAIL OLIVES | C43: 1312 | D43: 1312 | E43: =IF(C43=D43, "Same","New") -> Same | F43: 20 OZ | G43: 36.25 | H43: PERDIGON OLIVES 20 OZ | I43: =[1]Sheet1!I43 -> 322 | J43: =C43 & "_A1C1.webp" -> 1312_A1C1.webp | K43: =Sheet4!E43 -> 12
A44: OLIVES & PICKLED PRODUCTS/ OLIVES | B44: PERDIGON/ MANZANILLA COCKTAIL OLIVES | C44: 1317 | D44: 1317 | E44: =IF(C44=D44, "Same","New") -> Same | F44: 2.25 OZ | G44: 14.25 | H44: COCKTAIL PITTED OLIVES | I44: =[1]Sheet1!I44 -> 187 | J44: =C44 & "_A1C1.webp" -> 1317_A1C1.webp | K44: =Sheet4!E44 -> 12
A45: OLIVES & PICKLED PRODUCTS/ OLIVES | B45: PERDIGON/ MANZANILLA COCKTAIL OLIVES | C45: 1319 | D45: 1319 | E45: =IF(C45=D45, "Same","New") -> Same | F45: 5.5 OZ | G45: 41.75 | H45: COCKTAIL PITTED OLIVES 5.5 OZ | I45: =[1]Sheet1!I45 -> 1851 | J45: =C45 & "_A1C1.webp" -> 1319_A1C1.webp | K45: =Sheet4!E45 -> 24
...

Sheet Sheet4
A1: LAWSON COMPANY | B1: LAWSON LOCATION | C1: COMPANY | D1: PRODUCT NUMBER | E1: PACK SIZE | F1: PRODUCT SIZE | G1: PRODUCT PACKED TYPE | H1: PRODUCT DESCRIPTION | I1: QUANTITY ON HAND | J1: QUANTITY ON ORDER | K1: 8 WEEK DEMAND CYCLE | L1: AVG. DEMD | M1: WEEKLY SUPPLY | N1: AVAILABLE WEEKS SUPPLY
A2: 1 | B2: 100 | C2: 01 | D2: 1103 | E2: 36 | F2: 3 OZ | G2: BOT | H2: EXTRA VIRGIN OLIVE OIL 3 OZ | I2: 1067 | J2: 1260 | L2: 108.85 | M2: 21.4 | N2: 9.8
A3: 1 | B3: 100 | C3: 01 | D3: 1105 | E3: 25 | F3: 8.5 OZ | G3: BOT | H3: EXTRA VIRGIN OLIVE OIL 8.5 OZ | I3: 2799 | J3: 2808 | L3: 282.28 | M3: 19.9 | N3: 9.9
A4: 1 | B4: 100 | C4: 01 | D4: 1107 | E4: 12 | F4: 17 OZ | G4: BOT | H4: EXTRA VIRGIN OLIVE OIL 17 OZ | I4: 4070 | J4: 3610 | L4: 506.14 | M4: 15.2 | N4: 8
A5: 1 | B5: 100 | C5: 01 | D5: 1108 | E5: 9 | F5: 25.4 OZ | G5: BOT | H5: EXTRA VIRGIN OLIVE OIL 25.4 OZ | I5: 302 | J5: 180 | L5: 17.14 | M5: 28.1 | N5: 17.6
A6: 1 | B6: 100 | C6: 01 | D6: 1109 | E6: 9 | F6: 34 OZ | G6: BOT | H6: EXTRA VIRGIN OLIVE OIL 34 OZ | I6: 1453 | J6: 800 | L6: 112.71 | M6: 20 | N6: 12.9
A7: 1 | B7: 100 | C7: 01 | D7: 1111 | E7: 6 | F7: 50.7 OZ | G7: BOT | H7: EXTRA VIRGIN OLIVE OIL 50.7 OZ | I7: 134 | J7: 0 | L7: 7.42 | M7: 18.1 | N7: 18.1
A8: 1 | B8: 100 | C8: 01 | D8: 1120 | E8: 12 | F8: 24 OZ | G8: CAN | H8: EXTRA VIRGIN OLIVE OIL 24 OZ | I8: 3 | J8: 14 | L8: 0.57 | M8: 29.8 | N8: 5.3
A9: 1 | B9: 100 | C9: 01 | D9: 1128 | E9: 3 | F9: 101 OZ | G9: CAN | H9: EXTRA VIRGIN OLIVE OIL 3 LTS | I9: 78 | J9: 0 | L9: 3.57 | M9: 21.8 | N9: 21.8
A10: 1 | B10: 100 | C10: 01 | D10: 1130 | E10: 12 | F10: 17 OZ | G10: BOT | H10: GOYA UNICO XTRA VIRGIN OLV OIL | I10: 72 | J10: 95 | L10: 6.14 | M10: 27.2 | N10: 11.7
A11: 1 | B11: 100 | C11: 01 | D11: 1133 | E11: 12 | F11: 17 OZ | G11: BOT | H11: ORGANIC EXTRA VIRGIN OLIVE OIL | I11: 32 | J11: 285 | L11: 18 | M11: 17.6 | N11: 1.8
A12: 1 | B12: 100 | C12: 01 | D12: 1141 | E12: 25 | F12: 8.5 OZ | G12: BOT | H12: PURO OLIVE OIL 8.5 OZ | I12: 191 | J12: 1014 | L12: 66.71 | M12: 18.1 | N12: 2.9
A13: 1 | B13: 100 | C13: 01 | D13: 1142 | E13: 12 | F13: 17 OZ | G13: BOT | H13: PURO OLIVE OIL 17 OZ | I13: 352 | J13: 570 | L13: 45.14 | M13: 20.4 | N13: 7.8
... A24: 1 | B24: 100 | C24: 01 | D24: 1195 | E24: 12 | F24: 8.5 OZ | G24: BOT | H24: GARLIC EXTRA VIRGIN OLIVE OIL | I24: 90 | J24: 336 | L24: 21.57 | M24: 19.7 | N24: 4.2
A25: 1 | B25: 100 | C25: 01 | D25: 1199 | E25: 12 | F25: 5 OZ | H25: EXTRA VIRGIN OLIVE OIL SPRAY | I25: 555 | J25: 0 | L25: 25.14 | M25: 22.1 | N25: 22.1
A26: 1 | B26: 100 | C26: 01 | D26: 1222 | E26: 2 | F26: 280 OZ | G26: BOT | H26: PURE CORN OIL 280 OZ | I26: 157 | J26: 80 | L26: 6.28 | M26: 37.7 | N26: 25
A27: 1 | B27: 100 | C27: 01 | D27: 1227 | E27: 24 | F27: 16 OZ | G27: BOT | H27: PURE CORN OIL 16 OZ | I27: 486 | J27: 1280 | L27: 122.42 | M27: 14.4 | N27: 4
A28: 1 | B28: 100 | C28: 01 | D28: 1229 | E28: 12 | F28: 24 OZ | G28: BOT | H28: PURE CORN OIL 24 OZ | I28: 873 | J28: 1326 | L28: 191.42 | M28: 11.5 | N28: 4.6
A29: 1 | B29: 100 | C29: 01 | D29: 1231 | E29: 9 | F29: 48 OZ | G29: BOT | H29: PURE CORN OIL 48 OZ | I29: 482 | J29: 1560 | L29: 171.71 | M29: 11.9 | N29: 2.8
A30: 1 | B30: 100 | C30: 01 | D30: 1233 | E30: 6 | F30: 128 OZ | G30: BOT | H30: PURE CORN OIL 1 GAL | I30: 98 | J30: 252 | L30: 33 | M30: 10.6 | N30: 3
A31: 1 | B31: 100 | C31: 01 | D31: 1234 | E31: 6 | F31: 96 OZ | G31: BOT | H31: PURE CORN OIL 96 OZ | I31: 417 | J31: 72 | L31: 28 | M31: 17.5 | N31: 14.9
A32: 1 | B32: 100 | C32: 01 | D32: 1235 | E32: 24 | F32: 16 OZ | G32: BOT | H32: VEGETABLE OIL 16 OZ | I32: 642 | J32: 1080 | L32: 179.14 | M32: 9.6 | N32: 3.6
A33: 1 | B33: 100 | C33: 01 | D33: 1237 | E33: 12 | F33: 24 OZ | G33: BOT | H33: VEGETABLE OIL 24 OZ | I33: 1129 | J33: 2328 | L33: 301.57 | M33: 11.5 | N33: 3.7
A34: 1 | B34: 100 | C34: 01 | D34: 1239 | E34: 9 | F34: 48 OZ | G34: BOT | H34: VEGETABLE OIL 48 OZ | I34: 603 | J34: 2520 | L34: 276.57 | M34: 11.3 | N34: 2.2
A35: 1 | B35: 100 | C35: 01 | D35: 1240 | E35: 6 | F35: 96 OZ | G35: BOT | H35: VEGETABLE OIL 96 OZ | I35: 130 | J35: 396 | L35: 32.71 | M35: 16.1 | N35: 4
A36: 1 | B36: 100 | C36: 01 | D36: 1241 | E36: 6 | F36: 128 OZ | G36: BOT | H36: VEGETABLE OIL 1 GAL | I36: 308 | J36: 216 | L36: 28.71 | M36: 18.3 | N36: 10.7
A37: 1 | B37: 100 | C37: 01 | D37: 1250 | E37: 9 | F37: 48 OZ | G37: BOT | H37: CANOLA OIL 48 OZ | I37: 25 | J37: 1140 | L37: 99.28 | M37: 13.5 | N37: 0.3
A38: 1 | B38: 100 | C38: 01 | D38: 1251 | E38: 6 | F38: 96 OZ | H38: CANOLA OIL 96 OZ | I38: 166 | J38: 224 | L38: 6.85 | M38: 56.9 | N38: 24.2
A39: 1 | B39: 100 | C39: 01 | D39: 1255 | E39: 6 | F39: 25.4 OZ | G39: BOT | H39: GOYA AVOCADO OIL 25.4 OZ | I39: 1653 | J39: 2700 | L39: 138.28 | M39: 31.5 | N39: 12
A40: 1 | B40: 100 | C40: 01 | D40: 1304 | E40: 12 | F40: 9.5 OZ | G40: JAR | H40: PERDIGON OLIVES 12/9.5 OZ | I40: 72 | J40: 648 | L40: 17.42 | M40: 41.3 | N40: 4.1
A41: 1 | B41: 100 | C41: 01 | D41: 1307 | E41: 12 | F41: 3.75 OZ | G41: JAR | H41: MANZANILLA OLIVES | I41: 184 | J41: 192 | L41: 11.85 | M41: 31.7 | N41: 15.5
A42: 1 | B42: 100 | C42: 01 | D42: 1309 | E42: 12 | F42: 9.5 OZ | G42: JAR | H42: MANZANILLA OLIVES 9.5 OZ | I42: 675 | J42: 432 | L42: 48.71 | M42: 22.7 | N42: 13.9
A43: 1 | B43: 100 | C43: 01 | D43: 1312 | E43: 12 | F43: 20 OZ | G43: JAR | H43: PERDIGON OLIVES 20 OZ | I43: 205 | J43: 240 | L43: 11.71 | M43: 38 | N43: 17.5
A44: 1 | B44: 100 | C44: 01 | D44: 1317 | E44: 12 | F44: 2.25 OZ | G44: JAR | H44: COCKTAIL PITTED OLIVES | I44: 191 | J44: 560 | L44: 24.14 | M44: 31.1 | N44: 7.9
A45: 1 | B45: 100 | C45: 01 | D45: 1319 | E45: 24 | F45: 5.5 OZ | G45: JAR | H45: COCKTAIL PITTED OLIVES 5.5 OZ | I45: 1909 | J45: 2940 | L45: 241.42 | M45: 20.1 | N45: 7.9
A46: 1 | B46: 100 | C46: 01 | D46: 1327 | E46: 12 | F46: 3.75 OZ | G46: JAR | H46: STUFF MANZANILLA OLIVES | I46: 727 | J46: 768 | L46: 61.14 | M46: 24.5 | N46: 11.9
A47: 1 | B47: 100 | C47: 01 | D47: 1331 | E47: 12 | F47: 9.5 OZ | G47: JAR | H47: STUFF MANZANILLA OLIVES 9.5 OZ | I47: 2272 | J47: 3888 | L47: 274 | M47: 22.5 | N47: 8.3
A48: 1 | B48: 100 | C48: 01 | D48: 1332 | E48: 12 | F48: 20 OZ | G48: JAR | H48: STUFF MANZANILLA OLIVES 20 OZ | I48: 446 | J48: 600 | L48: 39.28 | M48: 26.6 | N48: 11.4
A49: 1 | B49: 100 | C49: 01 | D49: 1333 | E49: 12 | F49: 3.375 OZ | G49: JAR | H49: STUFFED QUEEN OLIVES | I49: 113 | J49: 192 | L49: 13.85 | M49: 22 | N49: 8.2
A50: 1 | B50: 100 | C50: 01 | D50: 1335 | E50: 12 | F50: 9 OZ | G50: JAR | H50: STUFFED QUEEN OLIVES 9 OZ | I50: 261 | J50: 324 | L50: 28.57 | M50: 20.5 | N50: 9.1
...

Sheet Sheet5

Sheet Sheet2
A1: # | B1: CATEGORIA | C1: SUBCATEGORIA | D1: ITEM # | E1: DESCRIPCION | F1: CASE COST | G1: UNIT COST | H1: UNIT PRICE | I1: SUGGEST RETAIL
A2: 1220 | B2: OLIVE OIL - OILS & LARD | C2: GOYA EXTRA VIRGIN OLIVE OIL | D2: 1103 | E2: 36/3 oz | F2: 77.50 | G2: 2.15 | H2: 15.41 | I2: 2.89
A3: 1221 | B3: OLIVE OIL - OILS & LARD | C3: GOYA EXTRA VIRGIN OLIVE OIL | D3: 1105 | E3: 25/8.5 oz | F3: 131.95 | G3: 5.28 | H3: 13.16 | I3: 6.99
A4: 1222 | B4: OLIVE OIL - OILS & LARD | C4: GOYA EXTRA VIRGIN OLIVE OIL | D4: 1107 | E4: 12/17 oz | F4: 120.50 | G4: 10.04 | H4: 12.60 | I4: 13.39
A5: 1223 | B5: OLIVE OIL - OILS & LARD | C5: GOYA EXTRA VIRGIN OLIVE OIL | D5: 1108 | E5: 9/25.4 oz | F5: 134.95 | G5: 14.99 | H5: 12.59 | I5: 19.99
A6: 1224 | B6: OLIVE OIL - OILS & LARD | C6: GOYA EXTRA VIRGIN OLIVE OIL | D6: 1109 | E6: 9/34 oz | F6: 169.95 | G6: 18.88 | H6: 11.85 | I6: 25.19
A7: 1225 | B7: OLIVE OIL - OILS & LARD | C7: GOYA EXTRA VIRGIN OLIVE OIL | D7: 1111 | E7: 6/50.7 oz | F7: 168.95 | G7: 28.16 | H7: 11.83 | I7: 37.49
A8: 1226 | B8: OLIVE OIL - OILS & LARD | C8: GOYA EXTRA VIRGIN OLIVE OIL | D8: 1120 | E8: 12/24 oz tin | F8: 171.95 | G8: 14.33 | H8: 12.66 | I8: 18.99
A9: 1227 | B9: OLIVE OIL - OILS & LARD | C9: GOYA EXTRA VIRGIN OLIVE OIL | D9: 1128 | E9: 3/3 liter (102 oz) tin | F9: 170.50 | G9: 56.83 | H9: 11.89 | I9: 75.79
A10: 1228 | B10: OLIVE OIL - OILS & LARD | C10: GOYA EXTRA VIRGIN OLIVE OIL | D10: 1130 | E10: 12/17 oz unico | F10: 144.95 | G10: 12.08 | H10: 15.05 | I10: 15.99
A11: 1229 | B11: OLIVE OIL - OILS & LARD | C11: GOYA EXTRA VIRGIN OLIVE OIL | D11: 1133 | E11: 12/17 oz organic | F11: 135.35 | G11: 11.28 | H11: 14.11 | I11: 14.99
A12: 1212 | B12: OLIVE OIL - OILS & LARD | C12: GOYA OLIVE OIL | D12: 1141 | E12: 25/8.5 oz puro olive oil | F12: 113.50 | G12: 4.54 | H12: 11.28 | I12: 5.99
A13: 1213 | B13: OLIVE OIL - OILS & LARD | C13: GOYA OLIVE OIL | D13: 1142 | E13: 12/17 oz puro olive oil | F13: 103.95 | G13: 8.66 | H13: 10.81 | I13: 11.49
... A101: 1355 | B101: PEPPERS - CHILES | C101: GOYA JAR/ JALAPENO PEPPERS | D101: 1686 | E101: 12/12 oz sliced jalapeno peppers | F101: 21.50 | G101: 1.79 | H101: 3.19 | I101: 2.39
A102: 102 | B102: BEANS, LENTILS, PEAS & BAGGED GRAINS | C102: BEANS READY TO EAT - GUISADAS 10.5 OZ. | D102: 1980 | E102: 24/ red kidney beans in sauce | F102: 22.95 | G102: 0.96 | H102: 1.97 | I102: 1.29
A103: 103 | B103: BEANS, LENTILS, PEAS & BAGGED GRAINS | C103: BEANS READY TO EAT - GUISADAS 10.5 OZ. | D103: 1981 | E103: 24/ pink beans in Ssauce | F103: 22.95 | G103: 0.96 | H103: 1.97 | I103: 1.29
A104: 104 | B104: BEANS, LENTILS, PEAS & BAGGED GRAINS | C104: BEANS READY TO EAT - GUISADAS 10.5 OZ. | D104: 1982 | E104: 24/ black bean soup | F104: 22.95 | G104: 0.96 | H104: 1.97 | I104: 1.29
A105: 105 | B105: BEANS, LENTILS, PEAS & BAGGED GRAINS | C105: BEANS READY TO EAT - GUISADAS 10.5 OZ. | D105: 1983 | E105: 24/15.5 oz pinto beans in sauce | F105: 22.95 | G105: 0.96 | H105: 1.97 | I105: 1.29
A106: 106 | B106: BEANS, LENTILS, PEAS & BAGGED GRAINS | C106: BEANS READY TO EAT - GUISADAS 10.5 OZ. | D106: 1984 | E106: 24/15.5 oz small reds in sauce | F106: 22.95 | G106: 0.96 | H106: 1.97 | I106: 1.29
A107: 107 | B107: BEANS, LENTILS, PEAS & BAGGED GRAINS | C107: BEANS READY TO EAT - GUISADAS 10.5 OZ. | D107: 1986 | E107: 24/15.5 oz chick peas in sauce | F107: 22.95 | G107: 0.96 | H107: 1.97 | I107: 1.29
A108: 9 | B108: BEANS, LENTILS, PEAS & BAGGED GRAINS | C108: GOYA PREMIUM BEANS, LENTILS & PEAS 15 OZ. / 15.5 OZ. | D108: 2001 | E108: 24/15 oz green pigeon peas | F108: 34.95 | G108: 1.46 | H108: 2.02 | I108: 1.89
A109: 77 | B109: BEANS, LENTILS, PEAS & BAGGED GRAINS | C109: GOYA LOW SODIUM BEANS & PEAS 15 OZ. / 15.5 OZ. | D109: 2002 | E109: 24/15 oz green pigeon peas low sodium | F109: 34.95 | G109: 1.46 | H109: 2.02 | I109: 1.89
A110: 45 | B110: BEANS, LENTILS, PEAS & BAGGED GRAINS | C110: GOYA PREMIUM BEANS & PEAS 29 OZ. / 30 OZ. | D110: 2003 | E110: 12/29 oz green pigeon peas | F110: 33.25 | G110: 2.77 | H110: 2.04 | I110: 3.69
A111: 70 | B111: BEANS, LENTILS, PEAS & BAGGED GRAINS | C111: GOYA PREMIUM BEANS & PEAS 100.7 OZ. / 110 OZ. | D111: 2004 | E111: 6/100.7 oz green pigeon peas | F111: 53.50 | G111: 8.92 | H111: 1.89 | I111: 11.89
A112: 10 | B112: BEANS, LENTILS, PEAS & BAGGED GRAINS | C112: GOYA PREMIUM BEANS, LENTILS & PEAS 15 OZ. / 15.5 OZ. | D112: 2005 | E112: 24/15 oz green pigeon peas with coconut | F112: 49.50 | G112: 2.06 | H112: 2.87 | I112: 2.69
A113: 46 | B113: BEANS, LENTILS, PEAS & BAGGED GRAINS | C113: GOYA PREMIUM BEANS & PEAS 29 OZ. / 30 OZ. | D113: 2006 | E113: 12/30 oz green pigeon peas with coconut milk | F113: 49.50 | G113: 4.13 | H113: 2.93 | I113: 5.49
A114: 39 | B114: BEANS, LENTILS, PEAS & BAGGED GRAINS | C114: GOYA PREMIUM BEANS & PEAS 15 OZ./15.5 OZ. - QTR PALLET | D114: 2007 | E114: 528/15 oz gandules | F114: 768.90 | G114: 1.46 | H114: 2.02 | I114: 1.89
A115: 94 | B115: BEANS, LENTILS, PEAS & BAGGED GRAINS | C115: GOYA ORGANIC BEANS & PEAS 15 OZ. / 15.5 OZ. | D115: 2009 | E115: 12/15 oz organic - green pigeon peas | F115: 20.95 | G115: 1.75 | H115: 2.44 | I115: 2.29
A116: 11 | B116: BEANS, LENTILS, PEAS & BAGGED GRAINS | C116: GOYA PREMIUM BEANS, LENTILS & PEAS 15 OZ. / 15.5 OZ. | D116: 2010 | E116: 24/15 oz pigeon peas with coconut | F116: 39.50 | G116: 1.65 | H116: 2.34 | I116: 2.19
A117: 37 | B117: BEANS, LENTILS, PEAS & BAGGED GRAINS | C117: GOYA PREMIUM BEANS, LENTILS & PEAS 15 OZ. / 15.5 OZ. | D117: 2021 | E117: 24/15.5 oz pigeon peas - EL JIBARITO | F117: 28.95 | G117: 1.21 | H117: 1.64 | I117: 1.59
A118: 61 | B118: BEANS, LENTILS, PEAS & BAGGED GRAINS | C118: GOYA PREMIUM BEANS & PEAS 29 OZ. / 30 OZ. | D118: 2022 | E118: 12/29 oz pigeon peas - El JIBARITO | F118: 27.25 | G118: 2.27 | H118: 1.65 | I118: 2.99
A119: 38 | B119: BEANS, LENTILS, PEAS & BAGGED GRAINS | C119: GOYA PREMIUM BEANS, LENTILS & PEAS 15 OZ. / 15.5 OZ. | D119: 2023 | E119: 24/15.5 oz pigeon peas with coconut - EL JIBARITO | F119: 39.50 | G119: 1.65 | H119: 2.34 | I119: 2.19
... A221: 13 | B221: BEANS, LENTILS, PEAS & BAGGED GRAINS | C221: GOYA PREMIUM BEANS, LENTILS & PEAS 15 OZ. / 15.5 OZ. | D221: 2402 | E221: 24/15.5 oz red kidney | F221: 26.40 | G221: 1.10 | H221: 1.54 | I221: 1.49
A222: 1 | B222: BEANS, LENTILS, PEAS & BAGGED GRAINS | C222: GOYA PREMIUM BEANS & PEAS 10.5 OZ. | D222: 2403 | E222: 24/ red kidney | F222: 22.50 | G222: .94 | H222: 1.9 | I222: 1.25
A223: 14 | B223: BEANS, LENTILS, PEAS & BAGGED GRAINS | C223: GOYA PREMIUM BEANS, LENTILS & PEAS 15 OZ. / 15.5 OZ. | D223: 2406 | E223: 24/15.5 oz pink beans | F223: 26.40 | G223: 1.10 | H223: 1.54 | I223: 1.49
A224: 2 | B224: BEANS, LENTILS, PEAS & BAGGED GRAINS | C224: GOYA PREMIUM BEANS & PEAS 10.5 OZ. | D224: 2407 | E224: 24/ pink beans | F224: 22.50 | G224: .94 | H224: 1.9 | I224: 1.25
A225: 49 | B225: BEANS, LENTILS, PEAS & BAGGED GRAINS | C225: GOYA PREMIUM BEANS & PEAS 29 OZ. / 30 OZ. | D225: 2410 | E225: 12/29 oz dark red kidney beans | F225: 25.95 | G225: 2.16 | H225: 1.59 | I225: 2.89
A226: 50 | B226: BEANS, LENTILS, PEAS & BAGGED GRAINS | C226: GOYA PREMIUM BEANS & PEAS 29 OZ. / 30 OZ. | D226: 2411 | E226: 12/29 oz pink beans | F226: 25.95 | G226: 2.16 | H226: 1.59 | I226: 2.89
A227: 15 | B227: BEANS, LENTILS, PEAS & BAGGED GRAINS | C227: GOYA PREMIUM BEANS, LENTILS & PEAS 15 OZ. / 15.5 OZ. | D227: 2412 | E227: 24/15.5 oz white | F227: 26.40 | G227: 1.10 | H227: 1.54 | I227: 1.49
A228: 3 | B228: BEANS, LENTILS, PEAS & BAGGED GRAINS | C228: GOYA PREMIUM BEANS & PEAS 10.5 OZ. | D228: 2413 | E228: 24/ white beans | F228: 22.5 | G228: .94 | H228: 1.9 | I228: 1.25
...

Sheet Sheet3
A1: 2706 | B1: Rice Mix Shipper (2) 48/7oz
A2: 4162 | B2: Parchment Paper
A3: 4165 | B3: Cotton Twine 2.6oz 800Ft
A4: 6438 | B4: Goya Saltine Crackers Red Tin
A5: 8801 | B5: Alpina Yogo Yogo Peach Drink
A6: 8802 | B6: Alpina Yogo Yogo Strawberry
A7: 4334 | B7: Goya Aloe Original Sugar Free
A8: 4335 | B8: Goya Aloe Original Organic
A9: 9505 | B9: Breadfruit Chunks
A10: 9411 | B10: Masa de Guineo
A11: 4536 | B11: Goya Queso Fresco
A12: 4537 | B12: Goya Queso Quesadilla
... A48: 5026 | B48: Goya 4-Pk Maria Cookies QT Plt
A49: 4368 | B49: Goya Chickpea Puff Chile Limon
A50: 4369 | B50: Chickpea Puffs Elote Mex Corn
A51: 4370 | B51: Goya Chickpea Puffs Churros
A52: 4374 | B52: Goya Chickpea Puffs Chile Limon
A53: 4408 | B53: Chickpea Puffs Elote Mex Corn
A54: 4409 | B54: Chickpea Puffs Churros
A55: 9514 | B55: Cheese and Guava Flan
A56: 3686 | B56: Goya Condensed Milk Easy Open
A57: 5990 | B57: Organic Thai Hom Mali Rice 2Lb
A58: 5991 | B58: Organic Thai Hom Mali Rice 5Lb
A59: 4512 | B59: Ducal Refried Red Bean DP 40oz
A60: 5993 | B60: Vegan Mexican Rice Mix 7oz
A61: 5963 | B61: Goya Yellow Corn Masarepa 25Lb.
