Workbook

Sheet Sheet1
B1: ='Numbers 2026'!A16 -> Week 14
B2: ='Numbers 2026'!D15 -> 66283 | C2: ='Numbers 2026'!J56 -> -311 | D2: ='Numbers 2026'!F56 -> -5394 | E2: ='Numbers 2026'!G56/100 -> -0.0063728733 | F2: =SUM(D2+(D2*0.02)) -> -5501.88
B3: Monday | C3: Tuesday | D3: Wednesday | E3: Thursday | F3: Friday | G3: VISITAR URGENTE
A4: 9AM | B4: Orlando Mendez | C4: Stop & Shop 857 | D4: Ali Abdalla (756472) | E4: Key Food 2560 Universal Elizabeth AFTER 11:30AM | F4: Fresh Grocer 144 | G4: Sazon Dominicano Latin American | H4: Nueva cuenta
A5: 9:30AM | B5: Mira Grocery Llc (Blitz) | C5: Kings Food Market | D5: DJR Service II LLC | E5: Elizabeth Truck Stop LLC | G5: Recuerdame Bonito Mexico | H5: Orden
A6: 0.4375 | B6: Family Market LLC | C6: Key Food 2602 074298 | D6: Jose Miguel Medina C12/29/00 (F9) | G6: Rankin St Deli Llc (Blitz) | H6: Orden
A7: 11 | C7: Shop Rite 162 | D7: Sara Velasquez C 2/10/06 (F9) | G7: Dollar Zone | H7: Nueva cuenta
A8: 12 | D8: Medina Liquors (Blitz) | G8: D-Chucho Antojitos LLC | H8: Orden (LLAMAR)
A9: 0.52083333 | B9: Mozzarepas/ Leon & CO Food services` CALL | H9: Orden
A10: 0.048611111 | B10: Reys Mini Market V Llc CALL | D10: Wal-Mart 3469 | H10: Orden
A11: 0.10416667 | B11: Wal-Mart 3469 | C11: Wal-Mart 3469 | G11: Asgp Party Supplies Llc | H11: Orden
A12: 0.15625 | G12: Elizabeth Truck Stop LLC | H12: Orden
A13: 0.19791667 | F13: Wal-Mart 3469
A14: 0.20833333
A15: 0.21875 | D15: Wal-Mart 3469
B16: SACARLE ORDEN | C16: ABRIR CUENTAS | D16: SACARLE ORDEN | E16: SACARLE ORDEN
B17: D-Chucho Antojitos LLC CALL 908-764-3233 | C17: Sazon Dominicano Latin American | D17: Elizabeth Mini Market Llc (Blitz) | E17: Rankin St Deli Llc (Blitz)
B19: Cust # | C19: Customer Name | D19: Delivered at | E19: Visit | F19: Days
B20: 743279 | C20: Sazon Dominicano Latin American | D20: NEW OWNER | E20: 45502 | F20: =TODAY()-D20 -> #VALUE!
B21: 756036 | C21: Recuerdame Bonito Mexico | D21: PAID | E21: 45594 | F21: =TODAY()-D21 -> #VALUE!
B22: 740937 | C22: Rankin St Deli Llc (Blitz) | D22: PAID | E22: 45691 | F22: =TODAY()-D22 -> #VALUE!
B23: 740142 | C23: Dollar Zone | D23: PAID | E23: 45701 | F23: =TODAY()-D23 -> #VALUE!
B24: 741014 | C24: D-Chucho Antojitos LLC | D24: CALL | E24: 45712 | F24: =TODAY()-D24 -> #VALUE!
B25: 740301 | C25: Elizabeth Mini Market Llc (Blitz) | D25: PAID | E25: 45805 | F25: =TODAY()-D25 -> #VALUE!
B26: 743270 | C26: Asgp Party Supplies Llc | D26: PAID | E26: 45810 | F26: =TODAY()-D26 -> #VALUE!
B27: 741721 | C27: Medina Liquors (Blitz) | D27: PAID | E27: 45970 | F27: =TODAY()-D27 -> #VALUE!
B28: 741346 | C28: Elizabeth Truck Stop LLC | D28: PAID | E28: 46069 | F28: =TODAY()-D28 -> #VALUE!
B29: 740934 | C29: Mira Grocery Llc (Blitz) | D29: PAID | E29: 46105 | F29: =TODAY()-D29 -> #VALUE!
B30: 741800 | C30: Reys Mini Market V Llc | D30: PAID | E30: 46113 | F30: =TODAY()-D30 -> #VALUE!
B31: 743284 | C31: Mozzarepas/ Leon & CO Food services` | D31: 46097 | E31: =D31+25 -> 46122 | F31: =TODAY()-D31 -> 27
B32: 741366 | C32: DJR Service II LLC | D32: 46098 | E32: =D32+25 -> 46123 | F32: =TODAY()-D32 -> 26
B33: 741720 | C33: Sara Velasquez C 2/10/06 (F9) | D33: 46099 | E33: =D33+25 -> 46124 | F33: =TODAY()-D33 -> 25
B34: 741360 | C34: Jose Miguel Medina C12/29/00 (F9) | D34: 46064 | E34: =D34+60 -> 46124 | F34: =TODAY()-D34 -> 60
B35: 741994 | C35: Family Market LLC | D35: PAID | E35: 46127 | F35: =TODAY()-D35 -> #VALUE!
B36: 740620 | C36: Ali Abdalla (756472) | D36: 46101 | E36: =D36+27 -> 46128 | F36: =TODAY()-D36 -> 23
B40: Biweekly | C40: Weekly | D40: Daily
B41: Rahway Garden Farm | C41: Orlando Mendez | D41: Wal-Mart 3469
B42: Dollar General 16678 | C42: Fresh Grocer 144 | D42: Wal-Mart 3469 Frozen
C43: Fresh Grocer 144 Frozen
C44: Key Food 2602 074298
...

Sheet Active 
A1: Cust # | B1: Customer Name | C1: Delivered at | D1: Visit | E1: Days | F1: Address | G1: City | H1: Order Frequency | I1: Pay | J1: Debe
A2: 742821 | B2: J & K Grocery Store LLC | C2: 0 | D2: 0 | E2: 0 | F2: 804 2nd Ave | G2: Elizabeth | H2: Monthly | I2: Monthly | J2: Changed Owner
A3: 743279 | B3: Sazon Dominicano Latin American | C3: NEW OWNER | D3: 45502 | E3: =TODAY()-C3 -> #VALUE! | F3: 380 saint georges ave | G3: Rahway | H3: Call/Monthly | I3: Monthly | J3: OWNER DOES NOT WANT GOYA
A4: 756036 | B4: Recuerdame Bonito Mexico | C4: PAID | D4: 45594 | E4: =TODAY()-C4 -> #VALUE! | F4: 407 South ave W | G4: Westfield | H4: Monthly | I4: CIA | J4: CLOSED
A5: 740937 | B5: Rankin St Deli Llc (Blitz) | C5: PAID | D5: 45691 | E5: =TODAY()-C5 -> #VALUE! | F5: 48 Rankin St | G5: Elizabeth | H5: Monthly | I5: CIA
A6: 740142 | B6: Dollar Zone | C6: PAID | D6: 45701 | E6: =TODAY()-C6 -> #VALUE! | F6: 860 W Edgar Rd | G6: Linden | H6: Biweekly | I6: Biweekly | J6: CLOSED
A7: 741014 | B7: D-Chucho Antojitos LLC | C7: CALL | D7: 45712 | E7: =TODAY()-C7 -> #VALUE! | F7: 307 Elizabeth ave | G7: Elizabeth | H7: Monthly | I7: Monthly | J7: New
A8: 740301 | B8: Elizabeth Mini Market Llc (Blitz) | C8: PAID | D8: 45805 | E8: =TODAY()-C8 -> #VALUE! | F8: 430 Elizabeth Ave | G8: Elizabeth | H8: Call/Monthly | I8: Monthly
A9: 743270 | B9: Asgp Party Supplies Llc | C9: PAID | D9: 45810 | E9: =TODAY()-C9 -> #VALUE! | F9: 736 W Grand Ave | G9: Rahway | H9: Monthly | I9: Monthly
A10: 741721 | B10: Medina Liquors (Blitz) | C10: PAID | D10: 45970 | E10: =TODAY()-C10 -> #VALUE! | F10: 709 E Jersey St | G10: Elizabeth | H10: Call/Monthly | I10: Monthly
A11: 741346 | B11: Elizabeth Truck Stop LLC | C11: PAID | D11: 46069 | E11: =TODAY()-C11 -> #VALUE! | F11: 600-610 Bond st | G11: Elizabeth | H11: Monthly | I11: Monthly
A12: 740934 | B12: Mira Grocery Llc (Blitz) | C12: PAID | D12: 46105 | E12: =TODAY()-C12 -> #VALUE! | F12: 134 5Th St | G12: Elizabeth | H12: Monthly | I12: Monthly
A13: 741800 | B13: Reys Mini Market V Llc | C13: PAID | D13: 46113 | E13: =TODAY()-C13 -> #VALUE! | F13: 462 Franklin St | G13: Elizabeth | H13: Monthly | I13: Monthly
A14: 743284 | B14: Mozzarepas/ Leon & CO Food services` | C14: 46097 | D14: =C14+25 -> 46122 | E14: =TODAY()-C14 -> 27 | F14: 6 Washignton st | G14: Clark | H14: Call/Monthly | I14: Monthly
A15: 741366 | B15: DJR Service II LLC | C15: 46098 | D15: =C15+25 -> 46123 | E15: =TODAY()-C15 -> 26 | F15: 500 Magnolia ave | G15: Elizabeth | H15: Monthly | I15: CIA
A16: 741720 | B16: Sara Velasquez C 2/10/06 (F9) | C16: 46099 | D16: =C16+25 -> 46124 | E16: =TODAY()-C16 -> 25 | F16: 714 E Jersey St | G16: Elizabeth | H16: Monthly | I16: Monthly
A17: 741360 | B17: Jose Miguel Medina C12/29/00 (F9) | C17: 46064 | D17: =C17+60 -> 46124 | E17: =TODAY()-C17 -> 60 | F17: 513 E Jersey St | G17: Elizabeth | H17: Monthly | I17: CIA
A18: 741994 | B18: Family Market LLC | C18: PAID | D18: 46127 | E18: =TODAY()-C18 -> #VALUE! | F18: 454 1St Ave | G18: Elizabeth | H18: Biweekly | I18: 0.01
A19: 740620 | B19: Ali Abdalla (756472) | C19: 46101 | D19: =C19+27 -> 46128 | E19: =TODAY()-C19 -> 23 | F19: 712 1st ave | G19: Elizabeth | H19: Weekly | I19: Monthly | J19: New
A20: 741901 | B20: La Poderosa Grocery | C20: 46107 | D20: =C20+25 -> 46132 | E20: =TODAY()-C20 -> 17 | F20: 882 Anna st | G20: Elizabeth | H20: Monthly | I20: Monthly
A21: 741710 | B21: Torres Market Llc (F9) | C21: 46107 | D21: =C21+25 -> 46132 | E21: =TODAY()-C21 -> 17 | F21: 863 E Jersey St | G21: Elizabeth | H21: Monthly | I21: Monthly
A22: 743263 | B22: El Almacen Mexicano | C22: 46108 | D22: =C22+25 -> 46133 | E22: =TODAY()-C22 -> 16 | F22: 1586 Irving St | G22: Rahway | H22: Monthly | I22: Monthly
A23: 742989 | B23: Rahway Minimart Corp (Blitz) | C23: 46112 | D23: =C23+25 -> 46137 | E23: =TODAY()-C23 -> 12 | F23: 297 W Grand Ave | G23: Rahway | H23: Monthly | I23: Monthly
A24: 741723 | B24: L&N Grocery Llc (F9) | C24: 46112 | D24: =C24+25 -> 46137 | E24: =TODAY()-C24 -> 12 | F24: 501 E. Jersey St | G24: Elizabeth | H24: Monthly | I24: Monthly
A25: 740232 | B25: Dollar General 16678 | C25: 46124 | D25: =C25+15 -> 46139 | E25: =TODAY()-C25 -> 0 | F25: 801 Livingston St | G25: Elizabeth | H25: Monthly | I25: Monthly
A26: 740450 | B26: Liz Mini Market LLC | C26: 46114 | D26: =C26+25 -> 46139 | E26: =TODAY()-C26 -> 10 | F26: 200 Erie st | G26: Elizabeth | H26: Monthly | I26: Monthly | J26: New
A27: 743141 | B27: Rahway Garden Farm | C27: 46122 | D27: =C27+20 -> 46142 | E27: =TODAY()-C27 -> 2 | F27: 1050 St George Ave | G27: Rahway | H27: Biweekly | I27: CIA
A28: 742972 | B28: 7 Eleven 11455 | C28: 46118 | D28: =C28+25 -> 46143 | E28: =TODAY()-C28 -> 6 | F28: 1265 Saint George Ave | G28: Colonia | H28: Call/Monthly | I28: Monthly
A29: 741364 | B29: Neighbor Mini Market 2 Llc (Blitz) | C29: 46119 | D29: =C29+25 -> 46144 | E29: =TODAY()-C29 -> 5 | F29: 561 Magnolia Ave | G29: Elizabeth | H29: Monthly | I29: Monthly
A30: 740235 | B30: Rio Via Supermarket Corp | C30: 46121 | D30: =C30+25 -> 46146 | E30: =TODAY()-C30 -> 3 | F30: 562 S. Park St | G30: Elizabeth | H30: Monthly | I30: Monthly
A31: 743295 | B31: Alejandro Flores 5/11/07 | C31: 46121 | D31: =C31+25 -> 46146 | E31: =TODAY()-C31 -> 3 | F31: 1534 Irving St | G31: Rahway | H31: Monthly | I31: Monthly
A32: 740304 | B32: Maminga Grocery & Deli Corp (Blitz) | C32: 46122 | D32: =C32+25 -> 46147 | E32: =TODAY()-C32 -> 2 | F32: 400 Elizabeth Ave | G32: Elizabeth | H32: Monthly | I32: Monthly
A33: 740370 | B33: N&R Deli & Grocery LLC | C33: 46122 | D33: =C33+25 -> 46147 | E33: =TODAY()-C33 -> 2 | F33: 65 Delaware st | G33: Elizabeth | H33: Monthly | I33: Monthly | J33: New
A34: 740452 | B34: Baleadas Supreme 2 LLC | C34: 46122 | D34: =C34+25 -> 46147 | E34: =TODAY()-C34 -> 2 | F34: 201 Erie st | G34: Elizabeth | H34: Monthly | I34: Monthly | J34: New
A35: 742822 | B35: J&K Grocery & Deli | C35: 46122 | D35: =C35+25 -> 46147 | E35: =TODAY()-C35 -> 2 | F35: 804 2nd Ave | G35: Elizabeth | H35: Monthly | I35: Monthly | J35: New
A36: 741368 | B36: YD&D Grocery Store LLC | C36: PAID | D36: CALL | E36: =TODAY()-C36 -> #VALUE! | F36: 544 2nd St | G36: Elizabeth | H36: Monthly | I36: Monthly
A37: 741504 | B37: Cakes By Ligia Limited Liability | C37: PAID | D37: CALL | E37: =TODAY()-C37 -> #VALUE! | F37: 8 Eastman St | G37: Cranford | H37: Call/Monthly | I37: Monthly
A38: 741362 | B38: Ron's Deli & Pastries (Blitz) | C38: PAID | D38: CALL | E38: =TODAY()-C38 -> #VALUE! | F38: 567 4Th Ave 1St Fl | G38: Elizabeth | H38: Monthly | I38: Monthly
A39: 756200 | B39: Pankag Patel (F) (C)10/95 | C39: PAID | D39: CALL | E39: =TODAY()-C39 -> #VALUE! | F39: 301 South Ave East | G39: Westfield | H39: Call/Monthly | I39: 0.01
A40: 742974 | B40: Fresh Grocer 144 | F40: 510 Inman Ave | G40: Colonia | H40: Weekly | I40: DD
...

Sheet Sheet2
A1: Cust # | B1: Customer Name | C1: Delivered at | D1: Visit | E1: Days | F1: Address | G1: City | H1: Order Frequency | I1: Pay
A2: 741721 | B2: Medina Liquors (Blitz) | C2: PAID | D2: 45970 | E2: =TODAY()-C2 -> #VALUE! | F2: 709 E Jersey St | G2: Elizabeth | H2: Call/Monthly | I2: Monthly
A3: 742972 | B3: 7 Eleven 11455 | C3: PAID | D3: 45985 | E3: =TODAY()-C3 -> #VALUE! | F3: 1265 Saint George Ave | G3: Colonia | H3: Call/Monthly | I3: Monthly
A4: 740235 | B4: Rio Via Supermarket Corp | C4: 46034 | D4: =C4+25 -> 46059 | E4: =TODAY()-C4 -> 90 | F4: 562 S. Park St | G4: Elizabeth | H4: Monthly | I4: Monthly
A5: 741901 | B5: La Poderosa Grocery | C5: 46035 | D5: =C5+25 -> 46060 | E5: =TODAY()-C5 -> 89 | F5: 882 Anna st | G5: Elizabeth | H5: Monthly | I5: Monthly
A6: 743284 | B6: Mozzarepas/ Leon & CO Food services` | C6: 46036 | D6: =C6+25 -> 46061 | E6: =TODAY()-C6 -> 88 | F6: 6 Washignton st | G6: Clark | H6: Call/Monthly | I6: Monthly
A7: 741364 | B7: Neighbor Mini Market 2 Llc (Blitz) | C7: 46037 | D7: =C7+25 -> 46062 | E7: =TODAY()-C7 -> 87 | F7: 561 Magnolia Ave | G7: Elizabeth | H7: Monthly | I7: Monthly
A8: 741710 | B8: Torres Market Llc (F9) | C8: PAID | D8: 46064 | E8: =TODAY()-C8 -> #VALUE! | F8: 863 E Jersey St | G8: Elizabeth | H8: Monthly | I8: Monthly
A9: 740620 | B9: Ali Abdalla (756472) | C9: 46037 | D9: =C9+27 -> 46064 | E9: =TODAY()-C9 -> 87 | F9: 712 1st ave | G9: Elizabeth | H9: Weekly | I9: Monthly
A10: 741346 | B10: Elizabeth Truck Stop LLC | C10: PAID | D10: 46069 | E10: =TODAY()-C10 -> #VALUE! | F10: 600-610 Bond st | G10: Elizabeth | H10: Monthly | I10: Monthly
A11: 740232 | B11: Dollar General 16678 | C11: 46056 | D11: =C11+15 -> 46071 | E11: =TODAY()-C11 -> 68 | F11: 801 Livingston St | G11: Elizabeth | H11: Monthly | I11: Monthly
A12: 741994 | B12: Family Market LLC | C12: 46066 | D12: =C12+7 -> 46073 | E12: =TODAY()-C12 -> 58 | F12: 454 1St Ave | G12: Elizabeth | H12: Biweekly | I12: 0.01
A13: 742974 | B13: Fresh Grocer 144 | F13: 510 Inman Ave | G13: Colonia | H13: Weekly | I13: DD
A14: 742977 | B14: Fresh Grocer 144 Dairy | F14: 510 Inman Ave | G14: Colonia | H14: Weekly | I14: DD
A15: 742976 | B15: Fresh Grocer 144 Deli | F15: 510 Inman Ave | G15: Colonia | H15: Weekly | I15: DD
A16: 742975 | B16: Fresh Grocer 144 Frozen | F16: 510 Inman Ave | G16: Colonia | H16: Weekly | I16: DD
A17: 742050 | B17: Orlando Mendez | F17: 547 Elizabeth Ave | G17: Elizabeth | H17: Weekly | I17: 0.01
A18: 756084 | B18: Kings Market 3620 | F18: 200 South Ave | G18: Garwood | H18: Weekly | I18: DD
A19: 756086 | B19: Kings Market 3620 Frozen | F19: 200 South Ave | G19: Garwood | H19: Weekly | I19: DD
A20: 756125 | B20: Shop Rite 162 | F20: 511 North | G20: Garwood | H20: Weekly | I20: DD
A21: 756128 | B21: Shop Rite 162 Deli | F21: 511 North Ave. | G21: Garwood | H21: Weekly | I21: DD
A22: 756131 | B22: Shop Rite 162 Direct | F22: 511 North Ave | G22: Garwood | H22: Weekly | I22: DD
A23: 756126 | B23: Shop Rite 162 Frozen | F23: 511 North Ave | G23: Garwood | H23: Weekly | I23: DD
A24: 740137 | B24: Wal-Mart 3469 | F24: 1000 W Edgar Rd | G24: Linden | H24: Daily | I24: DD
A25: 740138 | B25: Wal-Mart 3469 Frozen | F25: 1000 Edgar Rd | G25: Linden | H25: Daily | I25: DD
A26: 742984 | B26: Key Food 2602 074298 | F26: 2325 Elizabeth Ave | G26: Rahway | H26: Weekly | I26: DD
A27: 756025 | B27: Stop & Shop 857 | F27: 219 Elm St | G27: Westfield | H27: Weekly | I27: DD
A28: 756032 | B28: Stop & Shop 857 Deli | F28: 219 Elm St | G28: Westfield | H28: Weekly | I28: DD
A29: 741011 | B29: Key Food 2560 Universal Elizabeth | F29: 80 3rd St | G29: Elizabeth | H29: Weekly | I29: DD

Sheet Inactive
A1: Customer
A2: 742981 | B2: Universal Meat Mkt (Closed) | C2: 2325 Elizabeth Ave (No Del After 12 | D2: Rahway | E2: Closed
A3: 756082 | B3: Kings Market 43 | C3: 200 South Ave | D3: Garwood | E3: Changed Customer#
A4: 738240 | B4: Sime-S Marekt Llc (Blitz) | C4: 243 Stuyvesant Ave | D4: Newark | E4: Closing
A5: 737890 | B5: Dario Rivas C 1/6/06 Bd 7/29/2021 | C5: 89 Brookdale Ave | D5: Newark | E5: Owner Sold
A6: 730400 | B6: Alex Supermarket Corp (F9) | C6: 1140 Broad St | D6: Newark | E6: Closed
A7: 756083 | B7: Kings Market 43 Frozen | C7: 200 South Ave | D7: Garwood | E7: Changed Customer#
A8: 737510 | B8: Ramon Velez 9/14/07 | C8: 777 So Orange Ave | D8: Newark | E8: Don't want
A9: 740135 | B9: Wal-Mart 3469 | C9: 1601 Edgar Rd | D9: Linden | E9: Changed Customer#
A10: 740139 | B10: Zulia Grill Llc | C10: 222 S Stiles St | D10: Linden | E10: Closed
A11: 736733 | B11: Union Supermarket | C11: 944 18Th Ave | D11: Newark | E11: Changed Customer#
A12: 741993 | B12: Magical Sub Shop Llc (Blitz) | C12: 561 3Rd Ave | D12: Elizabeth | E12: Closed
A13: 740136 | B13: Wal-Mart #3469 Frozen | C13: 1601 Edgar Rd | D13: Linden | E13: Changed Customer#
A14: 741363 | B14: Neighbrhood Mini Market Llc (Blitz) | C14: 561-A Magnolia Ave | D14: Elizabeth | E14: Changed Customer#

Sheet Numbers 2026
J1: Proyeccion | K1: 0.02
A2: Week | B2: Days | C2: Weekly Quota | D2: 2025 | E2: 2026 | F2: Dif. Dollars | G2: % Chg. | H2: 2025 | I2: 2026 | J2: Diff Cases | K2: % Chg.
A3: Week 1 | B3: 45656 | C3: =D3+D3*$K$1 -> 60131.04 | D3: 58952 | E3: 76988 | F3: =E3-D3 -> 18036 | G3: =100*(E3-D3)/D3 -> 30.594382 | H3: 1851 | I3: 2341 | J3: =I3-H3 -> 490 | K3: =100*(I3-H3)/H3 -> 26.472177
A4: Week 2 | B4: =B3+7 -> 45663 | C4: =D4+D4*$K$1 -> 75286.2 | D4: 73810 | E4: 66160 | F4: =E4-D4 -> -7650 | G4: =100*(E4-D4)/D4 -> -10.364449 | H4: 2220 | I4: 2107 | J4: =I4-H4 -> -113 | K4: =100*(I4-H4)/H4 -> -5.0900901
A5: Week 3 | B5: =B4+7 -> 45670 | C5: =D5+D5*$K$1 -> 65187.18 | D5: 63909 | E5: 64831 | F5: =E5-D5 -> 922 | G5: =100*(E5-D5)/D5 -> 1.4426763 | H5: 1989 | I5: 1973 | J5: =I5-H5 -> -16 | K5: =100*(I5-H5)/H5 -> -0.80442433
A6: Week 4 | B6: =B5+7 -> 45677 | C6: =D6+D6*$K$1 -> 69629.28 | D6: 68264 | E6: 60252 | F6: =E6-D6 -> -8012 | G6: =100*(E6-D6)/D6 -> -11.736787 | H6: 2211 | I6: 1910 | J6: =I6-H6 -> -301 | K6: =100*(I6-H6)/H6 -> -13.613749
A7: Week 5 | B7: =B6+7 -> 45684 | C7: =D7+D7*$K$1 -> 63969.3 | D7: 62715 | E7: 69735 | F7: =E7-D7 -> 7020 | G7: =100*(E7-D7)/D7 -> 11.193494 | H7: 2012 | I7: 2109 | J7: =I7-H7 -> 97 | K7: =100*(I7-H7)/H7 -> 4.8210736
A8: Week 6 | B8: =B7+7 -> 45691 | C8: =D8+D8*$K$1 -> 73566.48 | D8: 72124 | E8: 68176 | F8: =E8-D8 -> -3948 | G8: =100*(E8-D8)/D8 -> -5.4739061 | H8: 2280 | I8: 2038 | J8: =I8-H8 -> -242 | K8: =100*(I8-H8)/H8 -> -10.614035
A9: Week 7 | B9: =B8+7 -> 45698 | C9: =D9+D9*$K$1 -> 60333 | D9: 59150 | E9: 54924 | F9: =E9-D9 -> -4226 | G9: =100*(E9-D9)/D9 -> -7.1445478 | H9: 1814 | I9: 1724 | J9: =I9-H9 -> -90 | K9: =100*(I9-H9)/H9 -> -4.9614112
A10: Week 8 | B10: =B9+7 -> 45705 | C10: =D10+D10*$K$1 -> 65111.7 | D10: 63835 | E10: 68796 | F10: =E10-D10 -> 4961 | G10: =100*(E10-D10)/D10 -> 7.7715987 | H10: 2030 | I10: 2676 | J10: =I10-H10 -> 646 | K10: =100*(I10-H10)/H10 -> 31.82266
A11: Week 9 | B11: =B10+7 -> 45712 | C11: =D11+D11*$K$1 -> 66038.88 | D11: 64744 | E11: 71822 | F11: =E11-D11 -> 7078 | G11: =100*(E11-D11)/D11 -> 10.932287 | H11: 2040 | I11: 2160 | J11: =I11-H11 -> 120 | K11: =100*(I11-H11)/H11 -> 5.8823529
A12: Week 10 | B12: =B11+7 -> 45719 | C12: =D12+D12*$K$1 -> 66608.04 | D12: 65302 | E12: 70464 | F12: =E12-D12 -> 5162 | G12: =100*(E12-D12)/D12 -> 7.9048115 | H12: 2104 | I12: 2143 | J12: =I12-H12 -> 39 | K12: =100*(I12-H12)/H12 -> 1.8536122
A13: Week 11 | B13: =B12+7 -> 45726 | C13: =D13+D13*$K$1 -> 71839.62 | D13: 70431 | E13: 52303 | F13: =E13-D13 -> -18128 | G13: =100*(E13-D13)/D13 -> -25.738666 | H13: 2381 | I13: 1615 | J13: =I13-H13 -> -766 | K13: =100*(I13-H13)/H13 -> -32.171357
A14: Week 12 | B14: =B13+7 -> 45733 | C14: =D14+D14*$K$1 -> 58018.62 | D14: 56881 | E14: 54834 | F14: =E14-D14 -> -2047 | G14: =100*(E14-D14)/D14 -> -3.5987412 | H14: 1834 | I14: 1867 | J14: =I14-H14 -> 33 | K14: =100*(I14-H14)/H14 -> 1.7993457
A15: Week 13 | B15: =B14+7 -> 45740 | C15: =D15+D15*$K$1 -> 67608.66 | D15: 66283 | E15: 61721 | F15: =E15-D15 -> -4562 | G15: =100*(E15-D15)/D15 -> -6.8826094 | H15: 2164 | I15: 1956 | J15: =I15-H15 -> -208 | K15: =100*(I15-H15)/H15 -> -9.6118299
A16: Week 14 | B16: =B15+7 -> 45747 | C16: =D16+D16*$K$1 -> 62781 | D16: 61550 | G16: =100*(E16-D16)/D16 -> -100 | H16: 1971 | K16: =100*(I16-H16)/H16 -> -100
A17: Week 15 | B17: =B16+7 -> 45754 | C17: =D17+D17*$K$1 -> 69949.56 | D17: 68578 | G17: =100*(E17-D17)/D17 -> -100 | H17: 2152 | K17: =100*(I17-H17)/H17 -> -100
A18: Week 16 | B18: =B17+7 -> 45761 | C18: =D18+D18*$K$1 -> 54394.56 | D18: 53328 | G18: =100*(E18-D18)/D18 -> -100 | H18: 1647 | K18: =100*(I18-H18)/H18 -> -100
A19: Week 17 | B19: =B18+7 -> 45768 | C19: =D19+D19*$K$1 -> 59133.48 | D19: 57974 | G19: =100*(E19-D19)/D19 -> -100 | H19: 1907 | K19: =100*(I19-H19)/H19 -> -100
A20: Week 18 | B20: =B19+7 -> 45775 | C20: =D20+D20*$K$1 -> 61831.38 | D20: 60619 | G20: =100*(E20-D20)/D20 -> -100 | H20: 1873 | K20: =100*(I20-H20)/H20 -> -100
A21: Week 19 | B21: =B20+7 -> 45782 | C21: =D21+D21*$K$1 -> 64185.54 | D21: 62927 | G21: =100*(E21-D21)/D21 -> -100 | H21: 1982 | K21: =100*(I21-H21)/H21 -> -100
A22: Week 20 | B22: =B21+7 -> 45789 | C22: =D22+D22*$K$1 -> 61706.94 | D22: 60497 | G22: =100*(E22-D22)/D22 -> -100 | H22: 2022 | K22: =100*(I22-H22)/H22 -> -100
A23: Week 21 | B23: =B22+7 -> 45796 | C23: =D23+D23*$K$1 -> 61635.54 | D23: 60427 | G23: =100*(E23-D23)/D23 -> -100 | H23: 1944 | K23: =100*(I23-H23)/H23 -> -100
A24: Week 22 | B24: =B23+7 -> 45803 | C24: =D24+D24*$K$1 -> 53935.56 | D24: 52878 | G24: =100*(E24-D24)/D24 -> -100 | H24: 1711 | K24: =100*(I24-H24)/H24 -> -100
A25: Week 23 | B25: =B24+7 -> 45810 | C25: =D25+D25*$K$1 -> 67004.82 | D25: 65691 | G25: =100*(E25-D25)/D25 -> -100 | H25: 2076 | K25: =100*(I25-H25)/H25 -> -100
A26: Week 24 | B26: =B25+7 -> 45817 | C26: =D26+D26*$K$1 -> 63361.38 | D26: 62119 | G26: =100*(E26-D26)/D26 -> -100 | H26: 1891 | K26: =100*(I26-H26)/H26 -> -100
A27: Week 25 | B27: =B26+7 -> 45824 | C27: =D27+D27*$K$1 -> 66617.22 | D27: 65311 | G27: =100*(E27-D27)/D27 -> -100 | H27: 1987 | K27: =100*(I27-H27)/H27 -> -100
... A55: Week 53 | B55: =B54+7 -> 46020 | C55: =D55+D55*$K$1 -> 64751.64 | D55: 63482 | G55: =100*(E55-D55)/D55 -> -100 | H55: 1980 | K55: =100*(I55-H55)/H55 -> -100
C56: =SUM(C3:C55) -> 3396372.5 | D56: =SUM(D3:D55) -> 3329777 | E56: =SUM(E3:E55) -> 841006 | F56: =SUM(F3:F55) -> -5394 | G56: =100*(F56)/(E56-F56) -> -0.63728733 | H56: =SUM(H3:H55) -> 104370 | I56: =SUM(I3:I55) -> 26619 | J56: =SUM(J3:J55) -> -311 | K56: =100*(J56)/(I56-J56) -> -1.1548459

Sheet Numbers 2025
J1: Proyeccion | K1: 0.02
A2: Week | B2: Days | C2: Weekly Quota | D2: 2024 | E2: 2025 | F2: Dif. Dollars | G2: % Chg. | H2: 2024 | I2: 2025 | J2: Diff Cases | K2: % Chg.
A3: Week 1 | B3: 45656 | C3: =D3+D3*$K$1 -> 65905.26 | D3: 64613 | E3: 58952 | F3: =E3-D3 -> -5661 | G3: =100*(E3-D3)/D3 -> -8.7613948 | H3: 1965 | I3: 1851 | J3: =I3-H3 -> -114 | K3: =100*(I3-H3)/H3 -> -5.8015267 | N3: 63059
A4: Week 2 | B4: =B3+7 -> 45663 | C4: =D4+D4*$K$1 -> 77883.12 | D4: 76356 | E4: 73810 | F4: =E4-D4 -> -2546 | G4: =100*(E4-D4)/D4 -> -3.3343811 | H4: 2342 | I4: 2220 | J4: =I4-H4 -> -122 | K4: =100*(I4-H4)/H4 -> -5.2092229 | N4: 74644
A5: Week 3 | B5: =B4+7 -> 45670 | C5: =D5+D5*$K$1 -> 66747.78 | D5: 65439 | E5: 63909 | F5: =E5-D5 -> -1530 | G5: =100*(E5-D5)/D5 -> -2.3380553 | H5: 2024 | I5: 1989 | J5: =I5-H5 -> -35 | K5: =100*(I5-H5)/H5 -> -1.729249 | N5: 64095
A6: Week 4 | B6: =B5+7 -> 45677 | C6: =D6+D6*$K$1 -> 89609.04 | D6: 87852 | E6: 68264 | F6: =E6-D6 -> -19588 | G6: =100*(E6-D6)/D6 -> -22.29659 | H6: 3424 | I6: 2211 | J6: =I6-H6 -> -1213 | K6: =100*(I6-H6)/H6 -> -35.426402 | N6: 86059
A7: Week 5 | B7: =B6+7 -> 45684 | C7: =D7+D7*$K$1 -> 62012.94 | D7: 60797 | E7: 62715 | F7: =E7-D7 -> 1918 | G7: =100*(E7-D7)/D7 -> 3.1547609 | H7: 1899 | I7: 2012 | J7: =I7-H7 -> 113 | K7: =100*(I7-H7)/H7 -> 5.9505003 | N7: 59229
A8: Week 6 | B8: =B7+7 -> 45691 | C8: =D8+D8*$K$1 -> 73824.54 | D8: 72377 | E8: 72124 | F8: =E8-D8 -> -253 | G8: =100*(E8-D8)/D8 -> -0.34955856 | H8: 2533 | I8: 2280 | J8: =I8-H8 -> -253 | K8: =100*(I8-H8)/H8 -> -9.9881563 | N8: 71421
A9: Week 7 | B9: =B8+7 -> 45698 | C9: =D9+D9*$K$1 -> 71019.54 | D9: 69627 | E9: 59150 | F9: =E9-D9 -> -10477 | G9: =100*(E9-D9)/D9 -> -15.047324 | H9: 2261 | I9: 1814 | J9: =I9-H9 -> -447 | K9: =100*(I9-H9)/H9 -> -19.770013 | N9: 67754
A10: Week 8 | B10: =B9+7 -> 45705 | C10: =D10+D10*$K$1 -> 67041.54 | D10: 65727 | E10: 63835 | F10: =E10-D10 -> -1892 | G10: =100*(E10-D10)/D10 -> -2.8785735 | H10: 2027 | I10: 2030 | J10: =I10-H10 -> 3 | K10: =100*(I10-H10)/H10 -> 0.14800197 | N10: 64901
A11: Week 9 | B11: =B10+7 -> 45712 | C11: =D11+D11*$K$1 -> 69133.56 | D11: 67778 | E11: 64744 | F11: =E11-D11 -> -3034 | G11: =100*(E11-D11)/D11 -> -4.4763788 | H11: 2152 | I11: 2040 | J11: =I11-H11 -> -112 | K11: =100*(I11-H11)/H11 -> -5.204461 | N11: 66457
A12: Week 10 | B12: =B11+7 -> 45719 | C12: =D12+D12*$K$1 -> 78672.6 | D12: 77130 | E12: 65302 | F12: =E12-D12 -> -11828 | G12: =100*(E12-D12)/D12 -> -15.335148 | H12: 2311 | I12: 2104 | J12: =I12-H12 -> -207 | K12: =100*(I12-H12)/H12 -> -8.9571614 | N12: 75732
A13: Week 11 | B13: =B12+7 -> 45726 | C13: =D13+D13*$K$1 -> 71157.24 | D13: 69762 | E13: 70431 | F13: =E13-D13 -> 669 | G13: =100*(E13-D13)/D13 -> 0.9589748 | H13: 2230 | I13: 2381 | J13: =I13-H13 -> 151 | K13: =100*(I13-H13)/H13 -> 6.7713004 | N13: 68139
A14: Week 12 | B14: =B13+7 -> 45733 | C14: =D14+D14*$K$1 -> 65963.4 | D14: 64670 | E14: 56881 | F14: =E14-D14 -> -7789 | G14: =100*(E14-D14)/D14 -> -12.044225 | H14: 2020 | I14: 1834 | J14: =I14-H14 -> -186 | K14: =100*(I14-H14)/H14 -> -9.2079208 | N14: 63446
A15: Week 13 | B15: =B14+7 -> 45740 | C15: =D15+D15*$K$1 -> 69666 | D15: 68300 | E15: 66283 | F15: =E15-D15 -> -2017 | G15: =100*(E15-D15)/D15 -> -2.9531479 | H15: 2144 | I15: 2164 | J15: =I15-H15 -> 20 | K15: =100*(I15-H15)/H15 -> 0.93283582 | N15: 67105
... A54: Week 52 | B54: =B53+7 -> 46013 | C54: =D54+D54*$K$1 -> 81366.42 | D54: 79771 | E54: 47543 | F54: =E54-D54 -> -32228 | G54: =100*(E54-D54)/D54 -> -40.400647 | H54: 2916 | I54: 1388 | J54: =I54-H54 -> -1528 | K54: =100*(I54-H54)/H54 -> -52.400549 | N54: 77716
A55: Week 53 | B55: =B54+7 -> 46020 | C55: =D55+D55*$K$1 -> 0 | D55: 0 | E55: 63482 | F55: =E55-D55 -> 63482 | G55: =100*(E55-D55)/D55 -> #DIV/0! | H55: 0 | I55: 1980 | J55: =I55-H55 -> 1980 | K55: =100*(I55-H55)/H55 -> #DIV/0!
C56: =SUM(C3:C55) -> 3613340.8 | D56: =SUM(D3:D54) -> 3542491 | E56: =SUM(E3:E55) -> 3328847 | F56: =SUM(F3:F55) -> -213644 | G56: =100*(F56)/(E56-F56) -> -6.0308975 | I56: =SUM(I3:I55) -> 104344 | J56: =SUM(J3:J55) -> -8109 | K56: =100*(J56)/(I56-J56) -> -7.2110126 | N56: =SUM(N3:N54) -> 3472049

Sheet Numbers 2024
A1: Week | B1: Days | C1: Weekly Quota | D1: 2023 | E1: 2024 | F1: Dif. Dollars | G1: % Chg. | H1: 2023 | I1: 2024 | J1: Diff Cases | K1: % Chg.
A2: Week 1 | B2: 45292 | C2: 62667 | D2: 56970 | E2: 65550 | F2: =E2-D2 -> 8580 | G2: =100*(E2-D2)/D2 -> 15.060558 | H2: 1828 | I2: 2057 | J2: =I2-H2 -> 229 | K2: =100*(I2-H2)/H2 -> 12.527352
A3: Week 2 | B3: =B2+7 -> 45299 | C3: 90315 | D3: 82105 | E3: 75464 | F3: =E3-D3 -> -6641 | G3: =100*(E3-D3)/D3 -> -8.0884234 | H3: 2647 | I3: 2328 | J3: =I3-H3 -> -319 | K3: =100*(I3-H3)/H3 -> -12.051379
A4: Week 3 | B4: =B3+7 -> 45306 | C4: 74878 | D4: 68071 | E4: 65403 | F4: =E4-D4 -> -2668 | G4: =100*(E4-D4)/D4 -> -3.9194371 | H4: 2112 | I4: 2039 | J4: =I4-H4 -> -73 | K4: =100*(I4-H4)/H4 -> -3.4564394
A5: Week 4 | B5: =B4+7 -> 45313 | C5: 83708 | D5: 76098 | E5: 94126 | F5: =E5-D5 -> 18028 | G5: =100*(E5-D5)/D5 -> 23.690504 | H5: 2515 | I5: 3831 | J5: =I5-H5 -> 1316 | K5: =100*(I5-H5)/H5 -> 52.326044
A6: Week 5 | B6: =B5+7 -> 45320 | C6: 78784 | D6: 71622 | E6: 64080 | F6: =E6-D6 -> -7542 | G6: =100*(E6-D6)/D6 -> -10.530284 | H6: 2322 | I6: 2060 | J6: =I6-H6 -> -262 | K6: =100*(I6-H6)/H6 -> -11.283376
A7: Week 6 | B7: =B6+7 -> 45327 | C7: 77972 | D7: 70883 | E7: 74858 | F7: =E7-D7 -> 3975 | G7: =100*(E7-D7)/D7 -> 5.6078326 | H7: 2364 | I7: 2441 | J7: =I7-H7 -> 77 | K7: =100*(I7-H7)/H7 -> 3.2571912
A8: Week 7 | B8: =B7+7 -> 45334 | C8: 80799 | D8: 73454 | E8: 65192 | F8: =E8-D8 -> -8262 | G8: =100*(E8-D8)/D8 -> -11.247856 | H8: 2413 | I8: 2093 | J8: =I8-H8 -> -320 | K8: =100*(I8-H8)/H8 -> -13.2615
A9: Week 8 | B9: =B8+7 -> 45341 | C9: 71236 | D9: 64760 | E9: 64279 | F9: =E9-D9 -> -481 | G9: =100*(E9-D9)/D9 -> -0.74274243 | H9: 2094 | I9: 1985 | J9: =I9-H9 -> -109 | K9: =100*(I9-H9)/H9 -> -5.2053486
A10: Week 9 | B10: =B9+7 -> 45348 | C10: 81013 | D10: 73648 | E10: 68779 | F10: =E10-D10 -> -4869 | G10: =100*(E10-D10)/D10 -> -6.6111775 | H10: 2371 | I10: 2099 | J10: =I10-H10 -> -272 | K10: =100*(I10-H10)/H10 -> -11.471953
A11: Week 10 | B11: =B10+7 -> 45355 | C11: 86970 | D11: 79064 | E11: 79500 | F11: =E11-D11 -> 436 | G11: =100*(E11-D11)/D11 -> 0.55145199 | H11: 2520 | I11: 2469 | J11: =I11-H11 -> -51 | K11: =100*(I11-H11)/H11 -> -2.0238095
A12: Week 11 | B12: =B11+7 -> 45362 | C12: 77347 | D12: 70315 | E12: 73243 | F12: =E12-D12 -> 2928 | G12: =100*(E12-D12)/D12 -> 4.1641186 | H12: 2257 | I12: 2353 | J12: =I12-H12 -> 96 | K12: =100*(I12-H12)/H12 -> 4.2534338
A13: Week 12 | B13: =B12+7 -> 45369 | C13: 71252 | D13: 64774 | E13: 64047 | F13: =E13-D13 -> -727 | G13: =100*(E13-D13)/D13 -> -1.1223639 | H13: 2111 | I13: 1967 | J13: =I13-H13 -> -144 | K13: =100*(I13-H13)/H13 -> -6.8214117
A14: Week 13 | B14: =B13+7 -> 45376 | C14: 77343 | D14: 70312 | E14: 67009 | F14: =E14-D14 -> -3303 | G14: =100*(E14-D14)/D14 -> -4.6976334 | H14: 2292 | I14: 2094 | J14: =I14-H14 -> -198 | K14: =100*(I14-H14)/H14 -> -8.6387435
... A53: Week 52 | B53: =B52+7 -> 45649 | C53: 70578 | D53: 64162 | E53: 80459 | F53: =E53-D53 -> 16297 | G53: =100*(E53-D53)/D53 -> 25.399769 | H53: 2046 | I53: 2966 | J53: =I53-H53 -> 920 | K53: =100*(I53-H53)/H53 -> 44.965787
C55: =SUM(C2:C54) -> 3950991 | D55: =SUM(D2:D54) -> 3591806 | E55: =SUM(E2:E54) -> 3609741 | F55: =SUM(F2:F54) -> 17935 | G55: =100*(F55)/(E55-F55) -> 0.49933098 | I55: =SUM(I2:I54) -> 115272 | J55: =SUM(J2:J54) -> 1173 | K55: =100*(J55)/(I55-J55) -> 1.0280546
B56: Average | C56: =SUM(C2:C54)/52 -> 75980.596 | D56: =SUM(D2:D54)/52 -> 69073.192

Sheet Numbers 2025 BEFORE CHANGES JUL
J1: Proyeccion | K1: 0.02
A2: Week | B2: Days | C2: Weekly Quota | D2: 2024 | E2: 2025 | F2: Dif. Dollars | G2: % Chg. | H2: 2024 | I2: 2025 | J2: Diff Cases | K2: % Chg.
A3: Week 1 | B3: 45656 | C3: =D3+D3*$K$1 -> 65740.02 | D3: 64451 | E3: 59221 | F3: =E3-D3 -> -5230 | G3: =100*(E3-D3)/D3 -> -8.1146918 | H3: 1966 | I3: 1866 | J3: =I3-H3 -> -100 | K3: =100*(I3-H3)/H3 -> -5.08647 | L3: =E3*0.04 -> 2368.84 | M3: =SUM(L3-(L3*0.015)-105) -> 2228.3074
A4: Week 2 | B4: =B3+7 -> 45663 | C4: =D4+D4*$K$1 -> 78943.92 | D4: 77396 | E4: 74030 | F4: =E4-D4 -> -3366 | G4: =100*(E4-D4)/D4 -> -4.349062 | H4: 2378 | I4: 2229 | J4: =I4-H4 -> -149 | K4: =100*(I4-H4)/H4 -> -6.2657696 | L4: =E4*0.04 -> 2961.2 | M4: =SUM(L4-(L4*0.015)-105) -> 2811.782
A5: Week 3 | B5: =B4+7 -> 45670 | C5: =D5+D5*$K$1 -> 66902.82 | D5: 65591 | E5: 64335 | F5: =E5-D5 -> -1256 | G5: =100*(E5-D5)/D5 -> -1.9148969 | H5: 2044 | I5: 2006 | J5: =I5-H5 -> -38 | K5: =100*(I5-H5)/H5 -> -1.8590998 | L5: =E5*0.04 -> 2573.4 | M5: =SUM(L5-(L5*0.015)-105) -> 2429.799
A6: Week 4 | B6: =B5+7 -> 45677 | C6: =D6+D6*$K$1 -> 89868.12 | D6: 88106 | E6: 68936 | F6: =E6-D6 -> -19170 | G6: =100*(E6-D6)/D6 -> -21.757883 | H6: 3427 | I6: 2240 | J6: =I6-H6 -> -1187 | K6: =100*(I6-H6)/H6 -> -34.636708 | L6: =E6*0.04 -> 2757.44 | M6: =SUM(L6-(L6*0.015)-105) -> 2611.0784
A7: Week 5 | B7: =B6+7 -> 45684 | C7: =D7+D7*$K$1 -> 62204.7 | D7: 60985 | E7: 63651 | F7: =E7-D7 -> 2666 | G7: =100*(E7-D7)/D7 -> 4.3715668 | H7: 1914 | I7: 2028 | J7: =I7-H7 -> 114 | K7: =100*(I7-H7)/H7 -> 5.9561129 | L7: =E7*0.04 -> 2546.04 | M7: =SUM(L7-(L7*0.015)-105) -> 2402.8494
A8: Week 6 | B8: =B7+7 -> 45691 | C8: =D8+D8*$K$1 -> 74354.94 | D8: 72897 | E8: 72828 | F8: =E8-D8 -> -69 | G8: =100*(E8-D8)/D8 -> -0.094654101 | H8: 2534 | I8: 2329 | J8: =I8-H8 -> -205 | K8: =100*(I8-H8)/H8 -> -8.0899763 | L8: =E8*0.04 -> 2913.12 | M8: =SUM(L8-(L8*0.015)-105) -> 2764.4232
A9: Week 7 | B9: =B8+7 -> 45698 | C9: =D9+D9*$K$1 -> 69978.12 | D9: 68606 | E9: 59254 | F9: =E9-D9 -> -9352 | G9: =100*(E9-D9)/D9 -> -13.631461 | H9: 2222 | I9: 1821 | J9: =I9-H9 -> -401 | K9: =100*(I9-H9)/H9 -> -18.046805 | L9: =E9*0.04 -> 2370.16 | M9: =SUM(L9-(L9*0.015)-105) -> 2229.6076
A10: Week 8 | B10: =B9+7 -> 45705 | C10: =D10+D10*$K$1 -> 67762.68 | D10: 66434 | E10: 64763 | F10: =E10-D10 -> -1671 | G10: =100*(E10-D10)/D10 -> -2.5152783 | H10: 2044 | I10: 2057 | J10: =I10-H10 -> 13 | K10: =100*(I10-H10)/H10 -> 0.63600783 | L10: =E10*0.04 -> 2590.52 | M10: =SUM(L10-(L10*0.015)-105) -> 2446.6622
A11: Week 9 | B11: =B10+7 -> 45712 | C11: =D11+D11*$K$1 -> 69215.16 | D11: 67858 | E11: 64340 | F11: =E11-D11 -> -3518 | G11: =100*(E11-D11)/D11 -> -5.1843556 | H11: 2156 | I11: 2048 | J11: =I11-H11 -> -108 | K11: =100*(I11-H11)/H11 -> -5.0092764 | L11: =E11*0.04 -> 2573.6 | M11: =SUM(L11-(L11*0.015)-105) -> 2429.996
A12: Week 10 | B12: =B11+7 -> 45719 | C12: =D12+D12*$K$1 -> 79122.42 | D12: 77571 | E12: 65530 | F12: =E12-D12 -> -12041 | G12: =100*(E12-D12)/D12 -> -15.522554 | H12: 2321 | I12: 2115 | J12: =I12-H12 -> -206 | K12: =100*(I12-H12)/H12 -> -8.8754847 | L12: =E12*0.04 -> 2621.2 | M12: =SUM(L12-(L12*0.015)-105) -> 2476.882
A13: Week 11 | B13: =B12+7 -> 45726 | C13: =D13+D13*$K$1 -> 71384.7 | D13: 69985 | E13: 70077 | F13: =E13-D13 -> 92 | G13: =100*(E13-D13)/D13 -> 0.13145674 | H13: 2246 | I13: 2368 | J13: =I13-H13 -> 122 | K13: =100*(I13-H13)/H13 -> 5.4318789 | L13: =E13*0.04 -> 2803.08 | M13: =SUM(L13-(L13*0.015)-105) -> 2656.0338
A14: Week 12 | B14: =B13+7 -> 45733 | C14: =D14+D14*$K$1 -> 66746.76 | D14: 65438 | E14: 57000 | F14: =E14-D14 -> -8438 | G14: =100*(E14-D14)/D14 -> -12.894648 | H14: 2038 | I14: 1857 | J14: =I14-H14 -> -181 | K14: =100*(I14-H14)/H14 -> -8.8812561 | L14: =E14*0.04 -> 2280 | M14: =SUM(L14-(L14*0.015)-105) -> 2140.8
A15: Week 13 | B15: =B14+7 -> 45740 | C15: =D15+D15*$K$1 -> 69888.36 | D15: 68518 | E15: 66462 | F15: =E15-D15 -> -2056 | G15: =100*(E15-D15)/D15 -> -3.0006714 | H15: 2152 | I15: 2165 | J15: =I15-H15 -> 13 | K15: =100*(I15-H15)/H15 -> 0.60408922 | L15: =E15*0.04 -> 2658.48 | M15: =SUM(L15-(L15*0.015)-105) -> 2513.6028
... A28: Week 26 | B28: =B27+7 -> 45831 | C28: =D28+D28*$K$1 -> 66425.46 | D28: 65123 | E28: 68765 | F28: =E28-D28 -> 3642 | G28: =100*(E28-D28)/D28 -> 5.5924942 | H28: 2265 | I28: 2223 | J28: =I28-H28 -> -42 | K28: =100*(I28-H28)/H28 -> -1.8543046 | L28: =E28*0.04 -> 2750.6 | M28: =SUM(L28-(L28*0.015)-105) -> 2604.341
A29: Week 27 | B29: =B28+7 -> 45838 | C29: =D29+D29*$K$1 -> 70761.48 | D29: 69374 | E29: 62534 | F29: =E29-D29 -> -6840 | G29: =100*(E29-D29)/D29 -> -9.8596016 | H29: 2208 | K29: =100*(I29-H29)/H29 -> -100 | L29: =E29*0.04 -> 2501.36 | M29: =SUM(L29-(L29*0.015)-105) -> 2358.8396
A30: Week 28 | B30: =B29+7 -> 45845 | C30: =D30+D30*$K$1 -> 62364.84 | D30: 61142 | G30: =100*(E30-D30)/D30 -> -100 | H30: 1860 | K30: =100*(I30-H30)/H30 -> -100
A31: Week 29 | B31: =B30+7 -> 45852 | C31: =D31+D31*$K$1 -> 72705.6 | D31: 71280 | G31: =100*(E31-D31)/D31 -> -100 | H31: 2230 | K31: =100*(I31-H31)/H31 -> -100
A32: Week 30 | B32: =B31+7 -> 45859 | C32: =D32+D32*$K$1 -> 64240.62 | D32: 62981 | G32: =100*(E32-D32)/D32 -> -100 | H32: 1985 | K32: =100*(I32-H32)/H32 -> -100
A33: Week 31 | B33: =B32+7 -> 45866 | C33: =D33+D33*$K$1 -> 55456.38 | D33: 54369 | G33: =100*(E33-D33)/D33 -> -100 | H33: 1762 | K33: =100*(I33-H33)/H33 -> -100
A34: Week 32 | B34: =B33+7 -> 45873 | C34: =D34+D34*$K$1 -> 89145.96 | D34: 87398 | G34: =100*(E34-D34)/D34 -> -100 | H34: 2695 | K34: =100*(I34-H34)/H34 -> -100
A35: Week 33 | B35: =B34+7 -> 45880 | C35: =D35+D35*$K$1 -> 63916.26 | D35: 62663 | G35: =100*(E35-D35)/D35 -> -100 | H35: 1962 | K35: =100*(I35-H35)/H35 -> -100
A36: Week 34 | B36: =B35+7 -> 45887 | C36: =D36+D36*$K$1 -> 74704.8 | D36: 73240 | G36: =100*(E36-D36)/D36 -> -100 | H36: 2286 | K36: =100*(I36-H36)/H36 -> -100
A37: Week 35 | B37: =B36+7 -> 45894 | C37: =D37+D37*$K$1 -> 65892 | D37: 64600 | G37: =100*(E37-D37)/D37 -> -100 | H37: 2226 | K37: =100*(I37-H37)/H37 -> -100
A38: Week 36 | B38: =B37+7 -> 45901 | C38: =D38+D38*$K$1 -> 66273.48 | D38: 64974 | G38: =100*(E38-D38)/D38 -> -100 | H38: 2031 | K38: =100*(I38-H38)/H38 -> -100
A39: Week 37 | B39: =B38+7 -> 45908 | C39: =D39+D39*$K$1 -> 72150.72 | D39: 70736 | G39: =100*(E39-D39)/D39 -> -100 | H39: 2275 | K39: =100*(I39-H39)/H39 -> -100
A40: Week 38 | B40: =B39+7 -> 45915 | C40: =D40+D40*$K$1 -> 65176.98 | D40: 63899 | G40: =100*(E40-D40)/D40 -> -100 | H40: 1963 | K40: =100*(I40-H40)/H40 -> -100
A41: Week 39 | B41: =B40+7 -> 45922 | C41: =D41+D41*$K$1 -> 53942.7 | D41: 52885 | G41: =100*(E41-D41)/D41 -> -100 | H41: 1695 | K41: =100*(I41-H41)/H41 -> -100
... A54: Week 52 | B54: =B53+7 -> 46013 | C54: =D54+D54*$K$1 -> 81949.86 | D54: 80343 | G54: =100*(E54-D54)/D54 -> -100 | H54: 2914 | K54: =100*(I54-H54)/H54 -> -100
C55: =SUM(C3:C54) -> 3640876.7 | D55: =SUM(D3:D54) -> 3569487 | E55: =SUM(E3:E54) -> 1716324 | F55: =SUM(F3:F54) -> -127408 | G55: =100*(F55)/(E55-F55) -> -6.9103319 | I55: =SUM(I3:I54) -> 52597 | J55: =SUM(J3:J54) -> -3956 | K55: =100*(J55)/(I55-J55) -> -6.995208
